Workbook

Sheet Data_Normalisasi
A1: ID | B1: X1_GPA | C1: X2_Income | D1: X3_Dependents | E1: X4_Achievements | F1: Class
A2: 1 | B2: 0.94444444 | C2: 0.060240964 | D2: 0.66666667 | E2: 0.9 | F2: 1
A3: 2 | B3: 0.86111111 | C3: 0.036144578 | D3: 0.83333333 | E3: 0.8 | F3: 1
A4: 3 | B4: 0.97222222 | C4: 0.12048193 | D4: 0.5 | E4: 1 | F4: 1
A5: 4 | B5: 0.83333333 | C5: 0.084337349 | D5: 0.66666667 | E5: 0.8 | F5: 1
A6: 5 | B6: 0.91666667 | C6: 0 | D6: 1 | E6: 0.9 | F6: 1
A7: 6 | B7: 0.88888889 | C7: 0.15662651 | D7: 0.5 | E7: 0.8 | F7: 1
A8: 7 | B8: 1 | C8: 0.072289157 | D8: 0.33333333 | E8: 1 | F8: 1
A9: 8 | B9: 0.80555556 | C9: 0.048192771 | D9: 0.83333333 | E9: 0.7 | F9: 1
A10: 9 | B10: 0.96111111 | C10: 0.13253012 | D10: 0.66666667 | E10: 0.9 | F10: 1
A11: 10 | B11: 0.87222222 | C11: 0.012048193 | D11: 0.83333333 | E11: 0.8 | F11: 1
A12: 11 | B12: 0.83888889 | C12: 0.10843373 | D12: 0.66666667 | E12: 0.7 | F12: 1
A13: 12 | B13: 0.98333333 | C13: 0.060240964 | D13: 0.5 | E13: 1 | F13: 1
... A51: 50 | B51: 0 | C51: 1 | D51: 0.16666667 | E51: 0 | F51: 3

Sheet Parameter_LVQ
A1: Parameter LVQ (diambil dari kode Python, ditanam sebagai konstanta)
A2: Prototipe | B2: X1_GPA | C2: X2_Income | D2: X3_Dependents | E2: X4_Achievements | F2: Class
A3: W1 | B3: 0.94444444 | C3: 0.060240964 | D3: 0.66666667 | E3: 0.9 | F3: 1
A4: W2 | B4: 0.58333333 | C4: 0.30120482 | D4: 0.5 | E4: 0.6 | F4: 2
A5: W3 | B5: 0.13888889 | C5: 0.78313253 | D5: 0.16666667 | E5: 0.2 | F5: 3

Sheet Manual_Epoch1
A1: Perhitungan Manual LVQ - Epoch 1 (50 data)
A2: Alpha (α) | B2: 0.3
A4: ID | B4: X1 | C4: X2 | D4: X3 | E4: X4 | F4: Target | G4: W1_x1 | H4: W1_x2 | I4: W1_x3 | J4: W1_x4 | K4: W2_x1 | L4: W2_x2 | M4: W2_x3 | N4: W2_x4 | O4: W3_x1 | P4: W3_x2 | Q4: W3_x3 | R4: W3_x4 | S4: d_W1 | T4: d_W2 | U4: d_W3 | V4: Winner | W4: Sign(+1/-1) | X4: W1_new_x1 | Y4: W1_new_x2 | Z4: W1_new_x3 | AA4: W1_new_x4 | AB4: W2_new_x1 | AC4: W2_new_x2 | AD4: W2_new_x3 | AE4: W2_new_x4 | AF4: W3_new_x1 | AG4: W3_new_x2 | AH4: W3_new_x3 | AI4: W3_new_x4
A5: 1 | B5: 0.94444444 | C5: 0.060240964 | D5: 0.66666667 | E5: 0.9 | F5: 1 | G5: 0.94444444 | H5: 0.060240964 | I5: 0.66666667 | J5: 0.9 | K5: 0.58333333 | L5: 0.30120482 | M5: 0.5 | N5: 0.6 | O5: 0.13888889 | P5: 0.78313253 | Q5: 0.16666667 | R5: 0.2 | S5: =SQRT((B5-G5)^2+(C5-H5)^2+(D5-I5)^2+(E5-J5)^2) -> 0 | T5: =SQRT((B5-K5)^2+(C5-L5)^2+(D5-M5)^2+(E5-N5)^2) -> 0.5533919 | U5: =SQRT((B5-O5)^2+(C5-P5)^2+(D5-Q5)^2+(E5-R5)^2) -> 1.3825672 | V5: =IF(S5=MIN(S5:U5),1,IF(T5=MIN(S5:U5),2,3)) -> 1 | W5: =IF(V5=1,IF(F5=1,1,-1),IF(V5=2,IF(F5=2,1,-1),IF(F5=3,1,-1))) -> 1 | X5: =IF(V5=1,G5+$B$2*W5*(B5-G5),G5) -> 0.94444444 | Y5: =IF(V5=1,H5+$B$2*W5*(C5-H5),H5) -> 0.060240964 | Z5: =IF(V5=1,I5+$B$2*W5*(D5-I5),I5) -> 0.66666667 | AA5: =IF(V5=1,J5+$B$2*W5*(E5-J5),J5) -> 0.9 | AB5: =IF(V5=2,K5+$B$2*W5*(B5-K5),K5) -> 0.58333333 | AC5: =IF(V5=2,L5+$B$2*W5*(C5-L5),L5) -> 0.30120482 | AD5: =IF(V5=2,M5+$B$2*W5*(D5-M5),M5) -> 0.5 | AE5: =IF(V5=2,N5+$B$2*W5*(E5-N5),N5) -> 0.6 | AF5: =IF(V5=3,O5+$B$2*W5*(B5-O5),O5) -> 0.13888889 | AG5: =IF(V5=3,P5+$B$2*W5*(C5-P5),P5) -> 0.78313253 | AH5: =IF(V5=3,Q5+$B$2*W5*(D5-Q5),Q5) -> 0.16666667 | AI5: =IF(V5=3,R5+$B$2*W5*(E5-R5),R5) -> 0.2
A6: 2 | B6: 0.86111111 | C6: 0.036144578 | D6: 0.83333333 | E6: 0.8 | F6: 1 | G6: =X5 -> 0.94444444 | H6: =Y5 -> 0.060240964 | I6: =Z5 -> 0.66666667 | J6: =AA5 -> 0.9 | K6: =AB5 -> 0.58333333 | L6: =AC5 -> 0.30120482 | M6: =AD5 -> 0.5 | N6: =AE5 -> 0.6 | ... R6: =AI5 -> 0.2 | S6: =SQRT((B6-G6)^2+(C6-H6)^2+(D6-I6)^2+(E6-J6)^2) -> 0.21284468 | T6: =SQRT((B6-K6)^2+(C6-L6)^2+(D6-M6)^2+(E6-N6)^2) -> 0.54637765 | U6: =SQRT((B6-O6)^2+(C6-P6)^2+(D6-Q6)^2+(E6-R6)^2) -> 1.3726035 | V6: =IF(S6=MIN(S6:U6),1,IF(T6=MIN(S6:U6),2,3)) -> 1 | W6: =IF(V6=1,IF(F6=1,1,-1),IF(V6=2,IF(F6=2,1,-1),IF(F6=3,1,-1))) -> 1 | X6: =IF(V6=1,G6+$B$2*W6*(B6-G6),G6) -> 0.91944444 | Y6: =IF(V6=1,H6+$B$2*W6*(C6-H6),H6) -> 0.053012048 | Z6: =IF(V6=1,I6+$B$2*W6*(D6-I6),I6) -> 0.71666667 | AA6: =IF(V6=1,J6+$B$2*W6*(E6-J6),J6) -> 0.87 | AB6: =IF(V6=2,K6+$B$2*W6*(B6-K6),K6) -> 0.58333333 | AC6: =IF(V6=2,L6+$B$2*W6*(C6-L6),L6) -> 0.30120482 | AD6: =IF(V6=2,M6+$B$2*W6*(D6-M6),M6) -> 0.5 | AE6: =IF(V6=2,N6+$B$2*W6*(E6-N6),N6) -> 0.6 | AF6: =IF(V6=3,O6+$B$2*W6*(B6-O6),O6) -> 0.13888889 | AG6: =IF(V6=3,P6+$B$2*W6*(C6-P6),P6) -> 0.78313253 | AH6: =IF(V6=3,Q6+$B$2*W6*(D6-Q6),Q6) -> 0.16666667 | AI6: =IF(V6=3,R6+$B$2*W6*(E6-R6),R6) -> 0.2
A7: 3 | B7: 0.97222222 | C7: 0.12048193 | D7: 0.5 | E7: 1 | F7: 1 | G7: =X6 -> 0.91944444 | H7: =Y6 -> 0.053012048 | I7: =Z6 -> 0.71666667 | J7: =AA6 -> 0.87 | K7: =AB6 -> 0.58333333 | L7: =AC6 -> 0.30120482 | M7: =AD6 -> 0.5 | N7: =AE6 -> 0.6 | ... R7: =AI6 -> 0.2 | S7: =SQRT((B7-G7)^2+(C7-H7)^2+(D7-I7)^2+(E7-J7)^2) -> 0.26679978 | T7: =SQRT((B7-K7)^2+(C7-L7)^2+(D7-M7)^2+(E7-N7)^2) -> 0.5864259 | U7: =SQRT((B7-O7)^2+(C7-P7)^2+(D7-Q7)^2+(E7-R7)^2) -> 1.3728297 | V7: =IF(S7=MIN(S7:U7),1,IF(T7=MIN(S7:U7),2,3)) -> 1 | W7: =IF(V7=1,IF(F7=1,1,-1),IF(V7=2,IF(F7=2,1,-1),IF(F7=3,1,-1))) -> 1 | X7: =IF(V7=1,G7+$B$2*W7*(B7-G7),G7) -> 0.93527778 | Y7: =IF(V7=1,H7+$B$2*W7*(C7-H7),H7) -> 0.073253012 | Z7: =IF(V7=1,I7+$B$2*W7*(D7-I7),I7) -> 0.65166667 | AA7: =IF(V7=1,J7+$B$2*W7*(E7-J7),J7) -> 0.909 | AB7: =IF(V7=2,K7+$B$2*W7*(B7-K7),K7) -> 0.58333333 | AC7: =IF(V7=2,L7+$B$2*W7*(C7-L7),L7) -> 0.30120482 | AD7: =IF(V7=2,M7+$B$2*W7*(D7-M7),M7) -> 0.5 | AE7: =IF(V7=2,N7+$B$2*W7*(E7-N7),N7) -> 0.6 | AF7: =IF(V7=3,O7+$B$2*W7*(B7-O7),O7) -> 0.13888889 | AG7: =IF(V7=3,P7+$B$2*W7*(C7-P7),P7) -> 0.78313253 | AH7: =IF(V7=3,Q7+$B$2*W7*(D7-Q7),Q7) -> 0.16666667 | AI7: =IF(V7=3,R7+$B$2*W7*(E7-R7),R7) -> 0.2
A8: 4 | B8: 0.83333333 | C8: 0.084337349 | D8: 0.66666667 | E8: 0.8 | F8: 1 | G8: =X7 -> 0.93527778 | H8: =Y7 -> 0.073253012 | I8: =Z7 -> 0.65166667 | J8: =AA7 -> 0.909 | K8: =AB7 -> 0.58333333 | L8: =AC7 -> 0.30120482 | M8: =AD7 -> 0.5 | N8: =AE7 -> 0.6 | ... R8: =AI7 -> 0.2 | S8: =SQRT((B8-G8)^2+(C8-H8)^2+(D8-I8)^2+(E8-J8)^2) -> 0.15040456 | T8: =SQRT((B8-K8)^2+(C8-L8)^2+(D8-M8)^2+(E8-N8)^2) -> 0.42108108 | U8: =SQRT((B8-O8)^2+(C8-P8)^2+(D8-Q8)^2+(E8-R8)^2) -> 1.2572063 | V8: =IF(S8=MIN(S8:U8),1,IF(T8=MIN(S8:U8),2,3)) -> 1 | W8: =IF(V8=1,IF(F8=1,1,-1),IF(V8=2,IF(F8=2,1,-1),IF(F8=3,1,-1))) -> 1 | X8: =IF(V8=1,G8+$B$2*W8*(B8-G8),G8) -> 0.90469444 | Y8: =IF(V8=1,H8+$B$2*W8*(C8-H8),H8) -> 0.076578313 | Z8: =IF(V8=1,I8+$B$2*W8*(D8-I8),I8) -> 0.65616667 | AA8: =IF(V8=1,J8+$B$2*W8*(E8-J8),J8) -> 0.8763 | AB8: =IF(V8=2,K8+$B$2*W8*(B8-K8),K8) -> 0.58333333 | AC8: =IF(V8=2,L8+$B$2*W8*(C8-L8),L8) -> 0.30120482 | AD8: =IF(V8=2,M8+$B$2*W8*(D8-M8),M8) -> 0.5 | AE8: =IF(V8=2,N8+$B$2*W8*(E8-N8),N8) -> 0.6 | AF8: =IF(V8=3,O8+$B$2*W8*(B8-O8),O8) -> 0.13888889 | AG8: =IF(V8=3,P8+$B$2*W8*(C8-P8),P8) -> 0.78313253 | AH8: =IF(V8=3,Q8+$B$2*W8*(D8-Q8),Q8) -> 0.16666667 | AI8: =IF(V8=3,R8+$B$2*W8*(E8-R8),R8) -> 0.2
A9: 5 | B9: 0.91666667 | C9: 0 | D9: 1 | E9: 0.9 | F9: 1 | G9: =X8 -> 0.90469444 | H9: =Y8 -> 0.076578313 | I9: =Z8 -> 0.65616667 | J9: =AA8 -> 0.8763 | K9: =AB8 -> 0.58333333 | L9: =AC8 -> 0.30120482 | M9: =AD8 -> 0.5 | N9: =AE8 -> 0.6 | ... R9: =AI8 -> 0.2 | S9: =SQRT((B9-G9)^2+(C9-H9)^2+(D9-I9)^2+(E9-J9)^2) -> 0.35325716 | T9: =SQRT((B9-K9)^2+(C9-L9)^2+(D9-M9)^2+(E9-N9)^2) -> 0.73609473 | U9: =SQRT((B9-O9)^2+(C9-P9)^2+(D9-Q9)^2+(E9-R9)^2) -> 1.5500578 | V9: =IF(S9=MIN(S9:U9),1,IF(T9=MIN(S9:U9),2,3)) -> 1 | W9: =IF(V9=1,IF(F9=1,1,-1),IF(V9=2,IF(F9=2,1,-1),IF(F9=3,1,-1))) -> 1 | X9: =IF(V9=1,G9+$B$2*W9*(B9-G9),G9) -> 0.90828611 | Y9: =IF(V9=1,H9+$B$2*W9*(C9-H9),H9) -> 0.053604819 | Z9: =IF(V9=1,I9+$B$2*W9*(D9-I9),I9) -> 0.75931667 | AA9: =IF(V9=1,J9+$B$2*W9*(E9-J9),J9) -> 0.88341 | AB9: =IF(V9=2,K9+$B$2*W9*(B9-K9),K9) -> 0.58333333 | AC9: =IF(V9=2,L9+$B$2*W9*(C9-L9),L9) -> 0.30120482 | AD9: =IF(V9=2,M9+$B$2*W9*(D9-M9),M9) -> 0.5 | AE9: =IF(V9=2,N9+$B$2*W9*(E9-N9),N9) -> 0.6 | AF9: =IF(V9=3,O9+$B$2*W9*(B9-O9),O9) -> 0.13888889 | AG9: =IF(V9=3,P9+$B$2*W9*(C9-P9),P9) -> 0.78313253 | AH9: =IF(V9=3,Q9+$B$2*W9*(D9-Q9),Q9) -> 0.16666667 | AI9: =IF(V9=3,R9+$B$2*W9*(E9-R9),R9) -> 0.2
A10: 6 | B10: 0.88888889 | C10: 0.15662651 | D10: 0.5 | E10: 0.8 | F10: 1 | G10: =X9 -> 0.90828611 | H10: =Y9 -> 0.053604819 | I10: =Z9 -> 0.75931667 | J10: =AA9 -> 0.88341 | K10: =AB9 -> 0.58333333 | L10: =AC9 -> 0.30120482 | M10: =AD9 -> 0.5 | N10: =AE9 -> 0.6 | ... R10: =AI9 -> 0.2 | S10: =SQRT((B10-G10)^2+(C10-H10)^2+(D10-I10)^2+(E10-J10)^2) -> 0.29187683 | T10: =SQRT((B10-K10)^2+(C10-L10)^2+(D10-M10)^2+(E10-N10)^2) -> 0.39276849 | U10: =SQRT((B10-O10)^2+(C10-P10)^2+(D10-Q10)^2+(E10-R10)^2) -> 1.194203 | V10: =IF(S10=MIN(S10:U10),1,IF(T10=MIN(S10:U10),2,3)) -> 1 | W10: =IF(V10=1,IF(F10=1,1,-1),IF(V10=2,IF(F10=2,1,-1),IF(F10=3,1,-1))) -> 1 | X10: =IF(V10=1,G10+$B$2*W10*(B10-G10),G10) -> 0.90246694 | Y10: =IF(V10=1,H10+$B$2*W10*(C10-H10),H10) -> 0.084511325 | Z10: =IF(V10=1,I10+$B$2*W10*(D10-I10),I10) -> 0.68152167 | AA10: =IF(V10=1,J10+$B$2*W10*(E10-J10),J10) -> 0.858387 | AB10: =IF(V10=2,K10+$B$2*W10*(B10-K10),K10) -> 0.58333333 | AC10: =IF(V10=2,L10+$B$2*W10*(C10-L10),L10) -> 0.30120482 | AD10: =IF(V10=2,M10+$B$2*W10*(D10-M10),M10) -> 0.5 | AE10: =IF(V10=2,N10+$B$2*W10*(E10-N10),N10) -> 0.6 | AF10: =IF(V10=3,O10+$B$2*W10*(B10-O10),O10) -> 0.13888889 | AG10: =IF(V10=3,P10+$B$2*W10*(C10-P10),P10) -> 0.78313253 | AH10: =IF(V10=3,Q10+$B$2*W10*(D10-Q10),Q10) -> 0.16666667 | AI10: =IF(V10=3,R10+$B$2*W10*(E10-R10),R10) -> 0.2
A11: 7 | B11: 1 | C11: 0.072289157 | D11: 0.33333333 | E11: 1 | F11: 1 | G11: =X10 -> 0.90246694 | H11: =Y10 -> 0.084511325 | I11: =Z10 -> 0.68152167 | J11: =AA10 -> 0.858387 | K11: =AB10 -> 0.58333333 | L11: =AC10 -> 0.30120482 | M11: =AD10 -> 0.5 | N11: =AE10 -> 0.6 | ... R11: =AI10 -> 0.2 | S11: =SQRT((B11-G11)^2+(C11-H11)^2+(D11-I11)^2+(E11-J11)^2) -> 0.38852469 | T11: =SQRT((B11-K11)^2+(C11-L11)^2+(D11-M11)^2+(E11-N11)^2) -> 0.6432661 | U11: =SQRT((B11-O11)^2+(C11-P11)^2+(D11-Q11)^2+(E11-R11)^2) -> 1.3836865 | V11: =IF(S11=MIN(S11:U11),1,IF(T11=MIN(S11:U11),2,3)) -> 1 | W11: =IF(V11=1,IF(F11=1,1,-1),IF(V11=2,IF(F11=2,1,-1),IF(F11=3,1,-1))) -> 1 | X11: =IF(V11=1,G11+$B$2*W11*(B11-G11),G11) -> 0.93172686 | Y11: =IF(V11=1,H11+$B$2*W11*(C11-H11),H11) -> 0.080844675 | Z11: =IF(V11=1,I11+$B$2*W11*(D11-I11),I11) -> 0.57706517 | AA11: =IF(V11=1,J11+$B$2*W11*(E11-J11),J11) -> 0.9008709 | AB11: =IF(V11=2,K11+$B$2*W11*(B11-K11),K11) -> 0.58333333 | AC11: =IF(V11=2,L11+$B$2*W11*(C11-L11),L11) -> 0.30120482 | AD11: =IF(V11=2,M11+$B$2*W11*(D11-M11),M11) -> 0.5 | AE11: =IF(V11=2,N11+$B$2*W11*(E11-N11),N11) -> 0.6 | AF11: =IF(V11=3,O11+$B$2*W11*(B11-O11),O11) -> 0.13888889 | AG11: =IF(V11=3,P11+$B$2*W11*(C11-P11),P11) -> 0.78313253 | AH11: =IF(V11=3,Q11+$B$2*W11*(D11-Q11),Q11) -> 0.16666667 | AI11: =IF(V11=3,R11+$B$2*W11*(E11-R11),R11) -> 0.2
A12: 8 | B12: 0.80555556 | C12: 0.048192771 | D12: 0.83333333 | E12: 0.7 | F12: 1 | G12: =X11 -> 0.93172686 | H12: =Y11 -> 0.080844675 | I12: =Z11 -> 0.57706517 | J12: =AA11 -> 0.9008709 | K12: =AB11 -> 0.58333333 | L12: =AC11 -> 0.30120482 | M12: =AD11 -> 0.5 | N12: =AE11 -> 0.6 | ... R12: =AI11 -> 0.2 | S12: =SQRT((B12-G12)^2+(C12-H12)^2+(D12-I12)^2+(E12-J12)^2) -> 0.35072473 | T12: =SQRT((B12-K12)^2+(C12-L12)^2+(D12-M12)^2+(E12-N12)^2) -> 0.48426121 | U12: =SQRT((B12-O12)^2+(C12-P12)^2+(D12-Q12)^2+(E12-R12)^2) -> 1.2957721 | V12: =IF(S12=MIN(S12:U12),1,IF(T12=MIN(S12:U12),2,3)) -> 1 | W12: =IF(V12=1,IF(F12=1,1,-1),IF(V12=2,IF(F12=2,1,-1),IF(F12=3,1,-1))) -> 1 | X12: =IF(V12=1,G12+$B$2*W12*(B12-G12),G12) -> 0.89387547 | Y12: =IF(V12=1,H12+$B$2*W12*(C12-H12),H12) -> 0.071049104 | Z12: =IF(V12=1,I12+$B$2*W12*(D12-I12),I12) -> 0.65394562 | AA12: =IF(V12=1,J12+$B$2*W12*(E12-J12),J12) -> 0.84060963 | AB12: =IF(V12=2,K12+$B$2*W12*(B12-K12),K12) -> 0.58333333 | AC12: =IF(V12=2,L12+$B$2*W12*(C12-L12),L12) -> 0.30120482 | AD12: =IF(V12=2,M12+$B$2*W12*(D12-M12),M12) -> 0.5 | AE12: =IF(V12=2,N12+$B$2*W12*(E12-N12),N12) -> 0.6 | AF12: =IF(V12=3,O12+$B$2*W12*(B12-O12),O12) -> 0.13888889 | AG12: =IF(V12=3,P12+$B$2*W12*(C12-P12),P12) -> 0.78313253 | AH12: =IF(V12=3,Q12+$B$2*W12*(D12-Q12),Q12) -> 0.16666667 | AI12: =IF(V12=3,R12+$B$2*W12*(E12-R12),R12) -> 0.2
A13: 9 | B13: 0.96111111 | C13: 0.13253012 | D13: 0.66666667 | E13: 0.9 | F13: 1 | G13: =X12 -> 0.89387547 | H13: =Y12 -> 0.071049104 | I13: =Z12 -> 0.65394562 | J13: =AA12 -> 0.84060963 | K13: =AB12 -> 0.58333333 | L13: =AC12 -> 0.30120482 | M13: =AD12 -> 0.5 | N13: =AE12 -> 0.6 | ... R13: =AI12 -> 0.2 | S13: =SQRT((B13-G13)^2+(C13-H13)^2+(D13-I13)^2+(E13-J13)^2) -> 0.10949698 | T13: =SQRT((B13-K13)^2+(C13-L13)^2+(D13-M13)^2+(E13-N13)^2) -> 0.53753603 | U13: =SQRT((B13-O13)^2+(C13-P13)^2+(D13-Q13)^2+(E13-R13)^2) -> 1.3562201 | V13: =IF(S13=MIN(S13:U13),1,IF(T13=MIN(S13:U13),2,3)) -> 1 | W13: =IF(V13=1,IF(F13=1,1,-1),IF(V13=2,IF(F13=2,1,-1),IF(F13=3,1,-1))) -> 1 | X13: =IF(V13=1,G13+$B$2*W13*(B13-G13),G13) -> 0.91404616 | Y13: =IF(V13=1,H13+$B$2*W13*(C13-H13),H13) -> 0.089493409 | Z13: =IF(V13=1,I13+$B$2*W13*(D13-I13),I13) -> 0.65776193 | AA13: =IF(V13=1,J13+$B$2*W13*(E13-J13),J13) -> 0.85842674 | AB13: =IF(V13=2,K13+$B$2*W13*(B13-K13),K13) -> 0.58333333 | AC13: =IF(V13=2,L13+$B$2*W13*(C13-L13),L13) -> 0.30120482 | AD13: =IF(V13=2,M13+$B$2*W13*(D13-M13),M13) -> 0.5 | AE13: =IF(V13=2,N13+$B$2*W13*(E13-N13),N13) -> 0.6 | AF13: =IF(V13=3,O13+$B$2*W13*(B13-O13),O13) -> 0.13888889 | AG13: =IF(V13=3,P13+$B$2*W13*(C13-P13),P13) -> 0.78313253 | AH13: =IF(V13=3,Q13+$B$2*W13*(D13-Q13),Q13) -> 0.16666667 | AI13: =IF(V13=3,R13+$B$2*W13*(E13-R13),R13) -> 0.2
A14: 10 | B14: 0.87222222 | C14: 0.012048193 | D14: 0.83333333 | E14: 0.8 | F14: 1 | G14: =X13 -> 0.91404616 | H14: =Y13 -> 0.089493409 | I14: =Z13 -> 0.65776193 | J14: =AA13 -> 0.85842674 | K14: =AB13 -> 0.58333333 | L14: =AC13 -> 0.30120482 | M14: =AD13 -> 0.5 | N14: =AE13 -> 0.6 | ... R14: =AI13 -> 0.2 | S14: =SQRT((B14-G14)^2+(C14-H14)^2+(D14-I14)^2+(E14-J14)^2) -> 0.20490487 | T14: =SQRT((B14-K14)^2+(C14-L14)^2+(D14-M14)^2+(E14-N14)^2) -> 0.56407398 | U14: =SQRT((B14-O14)^2+(C14-P14)^2+(D14-Q14)^2+(E14-R14)^2) -> 1.3916872 | V14: =IF(S14=MIN(S14:U14),1,IF(T14=MIN(S14:U14),2,3)) -> 1 | W14: =IF(V14=1,IF(F14=1,1,-1),IF(V14=2,IF(F14=2,1,-1),IF(F14=3,1,-1))) -> 1 | X14: =IF(V14=1,G14+$B$2*W14*(B14-G14),G14) -> 0.90149898 | Y14: =IF(V14=1,H14+$B$2*W14*(C14-H14),H14) -> 0.066259844 | Z14: =IF(V14=1,I14+$B$2*W14*(D14-I14),I14) -> 0.71043335 | AA14: =IF(V14=1,J14+$B$2*W14*(E14-J14),J14) -> 0.84089872 | AB14: =IF(V14=2,K14+$B$2*W14*(B14-K14),K14) -> 0.58333333 | AC14: =IF(V14=2,L14+$B$2*W14*(C14-L14),L14) -> 0.30120482 | AD14: =IF(V14=2,M14+$B$2*W14*(D14-M14),M14) -> 0.5 | AE14: =IF(V14=2,N14+$B$2*W14*(E14-N14),N14) -> 0.6 | AF14: =IF(V14=3,O14+$B$2*W14*(B14-O14),O14) -> 0.13888889 | AG14: =IF(V14=3,P14+$B$2*W14*(C14-P14),P14) -> 0.78313253 | AH14: =IF(V14=3,Q14+$B$2*W14*(D14-Q14),Q14) -> 0.16666667 | AI14: =IF(V14=3,R14+$B$2*W14*(E14-R14),R14) -> 0.2
A15: 11 | B15: 0.83888889 | C15: 0.10843373 | D15: 0.66666667 | E15: 0.7 | F15: 1 | G15: =X14 -> 0.90149898 | H15: =Y14 -> 0.066259844 | I15: =Z14 -> 0.71043335 | J15: =AA14 -> 0.84089872 | K15: =AB14 -> 0.58333333 | L15: =AC14 -> 0.30120482 | M15: =AD14 -> 0.5 | N15: =AE14 -> 0.6 | ... R15: =AI14 -> 0.2 | S15: =SQRT((B15-G15)^2+(C15-H15)^2+(D15-I15)^2+(E15-J15)^2) -> 0.1657306 | T15: =SQRT((B15-K15)^2+(C15-L15)^2+(D15-M15)^2+(E15-N15)^2) -> 0.37449581 | U15: =SQRT((B15-O15)^2+(C15-P15)^2+(D15-Q15)^2+(E15-R15)^2) -> 1.2021724 | V15: =IF(S15=MIN(S15:U15),1,IF(T15=MIN(S15:U15),2,3)) -> 1 | W15: =IF(V15=1,IF(F15=1,1,-1),IF(V15=2,IF(F15=2,1,-1),IF(F15=3,1,-1))) -> 1 | X15: =IF(V15=1,G15+$B$2*W15*(B15-G15),G15) -> 0.88271595 | Y15: =IF(V15=1,H15+$B$2*W15*(C15-H15),H15) -> 0.078912011 | Z15: =IF(V15=1,I15+$B$2*W15*(D15-I15),I15) -> 0.69730335 | AA15: =IF(V15=1,J15+$B$2*W15*(E15-J15),J15) -> 0.7986291 | AB15: =IF(V15=2,K15+$B$2*W15*(B15-K15),K15) -> 0.58333333 | AC15: =IF(V15=2,L15+$B$2*W15*(C15-L15),L15) -> 0.30120482 | AD15: =IF(V15=2,M15+$B$2*W15*(D15-M15),M15) -> 0.5 | AE15: =IF(V15=2,N15+$B$2*W15*(E15-N15),N15) -> 0.6 | AF15: =IF(V15=3,O15+$B$2*W15*(B15-O15),O15) -> 0.13888889 | AG15: =IF(V15=3,P15+$B$2*W15*(C15-P15),P15) -> 0.78313253 | AH15: =IF(V15=3,Q15+$B$2*W15*(D15-Q15),Q15) -> 0.16666667 | AI15: =IF(V15=3,R15+$B$2*W15*(E15-R15),R15) -> 0.2
A16: 12 | B16: 0.98333333 | C16: 0.060240964 | D16: 0.5 | E16: 1 | F16: 1 | G16: =X15 -> 0.88271595 | H16: =Y15 -> 0.078912011 | I16: =Z15 -> 0.69730335 | J16: =AA15 -> 0.7986291 | K16: =AB15 -> 0.58333333 | L16: =AC15 -> 0.30120482 | M16: =AD15 -> 0.5 | N16: =AE15 -> 0.6 | ... R16: =AI15 -> 0.2 | S16: =SQRT((B16-G16)^2+(C16-H16)^2+(D16-I16)^2+(E16-J16)^2) -> 0.29991885 | T16: =SQRT((B16-K16)^2+(C16-L16)^2+(D16-M16)^2+(E16-N16)^2) -> 0.61486875 | U16: =SQRT((B16-O16)^2+(C16-P16)^2+(D16-Q16)^2+(E16-R16)^2) -> 1.4095282 | V16: =IF(S16=MIN(S16:U16),1,IF(T16=MIN(S16:U16),2,3)) -> 1 | W16: =IF(V16=1,IF(F16=1,1,-1),IF(V16=2,IF(F16=2,1,-1),IF(F16=3,1,-1))) -> 1 | X16: =IF(V16=1,G16+$B$2*W16*(B16-G16),G16) -> 0.91290117 | Y16: =IF(V16=1,H16+$B$2*W16*(C16-H16),H16) -> 0.073310697 | Z16: =IF(V16=1,I16+$B$2*W16*(D16-I16),I16) -> 0.63811234 | AA16: =IF(V16=1,J16+$B$2*W16*(E16-J16),J16) -> 0.85904037 | AB16: =IF(V16=2,K16+$B$2*W16*(B16-K16),K16) -> 0.58333333 | AC16: =IF(V16=2,L16+$B$2*W16*(C16-L16),L16) -> 0.30120482 | AD16: =IF(V16=2,M16+$B$2*W16*(D16-M16),M16) -> 0.5 | AE16: =IF(V16=2,N16+$B$2*W16*(E16-N16),N16) -> 0.6 | AF16: =IF(V16=3,O16+$B$2*W16*(B16-O16),O16) -> 0.13888889 | AG16: =IF(V16=3,P16+$B$2*W16*(C16-P16),P16) -> 0.78313253 | AH16: =IF(V16=3,Q16+$B$2*W16*(D16-Q16),Q16) -> 0.16666667 | AI16: =IF(V16=3,R16+$B$2*W16*(E16-R16),R16) -> 0.2
A17: 13 | B17: 0.90555556 | C17: 0.14457831 | D17: 0.66666667 | E17: 0.8 | F17: 1 | G17: =X16 -> 0.91290117 | H17: =Y16 -> 0.073310697 | I17: =Z16 -> 0.63811234 | J17: =AA16 -> 0.85904037 | K17: =AB16 -> 0.58333333 | L17: =AC16 -> 0.30120482 | M17: =AD16 -> 0.5 | N17: =AE16 -> 0.6 | ... R17: =AI16 -> 0.2 | S17: =SQRT((B17-G17)^2+(C17-H17)^2+(D17-I17)^2+(E17-J17)^2) -> 0.097129533 | T17: =SQRT((B17-K17)^2+(C17-L17)^2+(D17-M17)^2+(E17-N17)^2) -> 0.44287335 | U17: =SQRT((B17-O17)^2+(C17-P17)^2+(D17-Q17)^2+(E17-R17)^2) -> 1.2670948 | V17: =IF(S17=MIN(S17:U17),1,IF(T17=MIN(S17:U17),2,3)) -> 1 | W17: =IF(V17=1,IF(F17=1,1,-1),IF(V17=2,IF(F17=2,1,-1),IF(F17=3,1,-1))) -> 1 | X17: =IF(V17=1,G17+$B$2*W17*(B17-G17),G17) -> 0.91069748 | Y17: =IF(V17=1,H17+$B$2*W17*(C17-H17),H17) -> 0.094690982 | Z17: =IF(V17=1,I17+$B$2*W17*(D17-I17),I17) -> 0.64667864 | AA17: =IF(V17=1,J17+$B$2*W17*(E17-J17),J17) -> 0.84132826 | AB17: =IF(V17=2,K17+$B$2*W17*(B17-K17),K17) -> 0.58333333 | AC17: =IF(V17=2,L17+$B$2*W17*(C17-L17),L17) -> 0.30120482 | AD17: =IF(V17=2,M17+$B$2*W17*(D17-M17),M17) -> 0.5 | AE17: =IF(V17=2,N17+$B$2*W17*(E17-N17),N17) -> 0.6 | AF17: =IF(V17=3,O17+$B$2*W17*(B17-O17),O17) -> 0.13888889 | AG17: =IF(V17=3,P17+$B$2*W17*(C17-P17),P17) -> 0.78313253 | AH17: =IF(V17=3,Q17+$B$2*W17*(D17-Q17),Q17) -> 0.16666667 | AI17: =IF(V17=3,R17+$B$2*W17*(E17-R17),R17) -> 0.2
... A54: 50 | B54: 0 | C54: 1 | D54: 0.16666667 | E54: 0 | F54: 3 | G54: =X53 -> 0.91020347 | H54: =Y53 -> 0.085648558 | I54: =Z53 -> 0.67066754 | J54: =AA53 -> 0.84751292 | K54: =AB53 -> 0.59262299 | L54: =AC53 -> 0.36896271 | M54: =AD53 -> 0.46829442 | N54: =AE53 -> 0.48332891 | ... R54: =AI53 -> 0.17262602 | S54: =SQRT((B54-G54)^2+(C54-H54)^2+(D54-I54)^2+(E54-J54)^2) -> 1.6238239 | T54: =SQRT((B54-K54)^2+(C54-L54)^2+(D54-M54)^2+(E54-N54)^2) -> 1.0363379 | U54: =SQRT((B54-O54)^2+(C54-P54)^2+(D54-Q54)^2+(E54-R54)^2) -> 0.35870242 | V54: =IF(S54=MIN(S54:U54),1,IF(T54=MIN(S54:U54),2,3)) -> 3 | W54: =IF(V54=1,IF(F54=1,1,-1),IF(V54=2,IF(F54=2,1,-1),IF(F54=3,1,-1))) -> 1 | X54: =IF(V54=1,G54+$B$2*W54*(B54-G54),G54) -> 0.91020347 | Y54: =IF(V54=1,H54+$B$2*W54*(C54-H54),H54) -> 0.085648558 | Z54: =IF(V54=1,I54+$B$2*W54*(D54-I54),I54) -> 0.67066754 | AA54: =IF(V54=1,J54+$B$2*W54*(E54-J54),J54) -> 0.84751292 | AB54: =IF(V54=2,K54+$B$2*W54*(B54-K54),K54) -> 0.59262299 | AC54: =IF(V54=2,L54+$B$2*W54*(C54-L54),L54) -> 0.36896271 | AD54: =IF(V54=2,M54+$B$2*W54*(D54-M54),M54) -> 0.46829442 | AE54: =IF(V54=2,N54+$B$2*W54*(E54-N54),N54) -> 0.48332891 | AF54: =IF(V54=3,O54+$B$2*W54*(B54-O54),O54) -> 0.1424351 | AG54: =IF(V54=3,P54+$B$2*W54*(C54-P54),P54) -> 0.83224995 | AH54: =IF(V54=3,Q54+$B$2*W54*(D54-Q54),Q54) -> 0.17082942 | AI54: =IF(V54=3,R54+$B$2*W54*(E54-R54),R54) -> 0.12083822

Sheet Manual_Epoch2
A1: Perhitungan Manual LVQ - Epoch 2 (50 data)
A2: Alpha (α) | B2: 0.27
A4: ID | B4: X1 | C4: X2 | D4: X3 | E4: X4 | F4: Target | G4: W1_x1 | H4: W1_x2 | I4: W1_x3 | J4: W1_x4 | K4: W2_x1 | L4: W2_x2 | M4: W2_x3 | N4: W2_x4 | O4: W3_x1 | P4: W3_x2 | Q4: W3_x3 | R4: W3_x4 | S4: d_W1 | T4: d_W2 | U4: d_W3 | V4: Winner | W4: Sign(+1/-1) | X4: W1_new_x1 | Y4: W1_new_x2 | Z4: W1_new_x3 | AA4: W1_new_x4 | AB4: W2_new_x1 | AC4: W2_new_x2 | AD4: W2_new_x3 | AE4: W2_new_x4 | AF4: W3_new_x1 | AG4: W3_new_x2 | AH4: W3_new_x3 | AI4: W3_new_x4
A5: 1 | B5: 0.94444444 | C5: 0.060240964 | D5: 0.66666667 | E5: 0.9 | F5: 1 | G5: =Manual_Epoch1!X54 -> 0.91020347 | H5: =Manual_Epoch1!Y54 -> 0.085648558 | I5: =Manual_Epoch1!Z54 -> 0.67066754 | J5: =Manual_Epoch1!AA54 -> 0.84751292 | K5: =Manual_Epoch1!AB54 -> 0.59262299 | L5: =Manual_Epoch1!AC54 -> 0.36896271 | M5: =Manual_Epoch1!AD54 -> 0.46829442 | N5: =Manual_Epoch1!AE54 -> 0.48332891 | ... R5: =Manual_Epoch1!AI54 -> 0.12083822 | S5: =SQRT((B5-G5)^2+(C5-H5)^2+(D5-I5)^2+(E5-J5)^2) -> 0.067741357 | T5: =SQRT((B5-K5)^2+(C5-L5)^2+(D5-M5)^2+(E5-N5)^2) -> 0.657308 | U5: =SQRT((B5-O5)^2+(C5-P5)^2+(D5-Q5)^2+(E5-R5)^2) -> 1.4464317 | V5: =IF(S5=MIN(S5:U5),1,IF(T5=MIN(S5:U5),2,3)) -> 1 | W5: =IF(V5=1,IF(F5=1,1,-1),IF(V5=2,IF(F5=2,1,-1),IF(F5=3,1,-1))) -> 1 | X5: =IF(V5=1,G5+$B$2*W5*(B5-G5),G5) -> 0.91944853 | Y5: =IF(V5=1,H5+$B$2*W5*(C5-H5),H5) -> 0.078788507 | Z5: =IF(V5=1,I5+$B$2*W5*(D5-I5),I5) -> 0.66958731 | AA5: =IF(V5=1,J5+$B$2*W5*(E5-J5),J5) -> 0.86168443 | AB5: =IF(V5=2,K5+$B$2*W5*(B5-K5),K5) -> 0.59262299 | AC5: =IF(V5=2,L5+$B$2*W5*(C5-L5),L5) -> 0.36896271 | AD5: =IF(V5=2,M5+$B$2*W5*(D5-M5),M5) -> 0.46829442 | AE5: =IF(V5=2,N5+$B$2*W5*(E5-N5),N5) -> 0.48332891 | AF5: =IF(V5=3,O5+$B$2*W5*(B5-O5),O5) -> 0.1424351 | AG5: =IF(V5=3,P5+$B$2*W5*(C5-P5),P5) -> 0.83224995 | AH5: =IF(V5=3,Q5+$B$2*W5*(D5-Q5),Q5) -> 0.17082942 | AI5: =IF(V5=3,R5+$B$2*W5*(E5-R5),R5) -> 0.12083822
A6: 2 | B6: 0.86111111 | C6: 0.036144578 | D6: 0.83333333 | E6: 0.8 | F6: 1 | G6: =X5 -> 0.91944853 | H6: =Y5 -> 0.078788507 | I6: =Z5 -> 0.66958731 | J6: =AA5 -> 0.86168443 | K6: =AB5 -> 0.59262299 | L6: =AC5 -> 0.36896271 | M6: =AD5 -> 0.46829442 | N6: =AE5 -> 0.48332891 | ... R6: =AI5 -> 0.12083822 | S6: =SQRT((B6-G6)^2+(C6-H6)^2+(D6-I6)^2+(E6-J6)^2) -> 0.1893132 | T6: =SQRT((B6-K6)^2+(C6-L6)^2+(D6-M6)^2+(E6-N6)^2) -> 0.64528116 | U6: =SQRT((B6-O6)^2+(C6-P6)^2+(D6-Q6)^2+(E6-R6)^2) -> 1.4319396 | V6: =IF(S6=MIN(S6:U6),1,IF(T6=MIN(S6:U6),2,3)) -> 1 | W6: =IF(V6=1,IF(F6=1,1,-1),IF(V6=2,IF(F6=2,1,-1),IF(F6=3,1,-1))) -> 1 | X6: =IF(V6=1,G6+$B$2*W6*(B6-G6),G6) -> 0.90369743 | Y6: =IF(V6=1,H6+$B$2*W6*(C6-H6),H6) -> 0.067274647 | Z6: =IF(V6=1,I6+$B$2*W6*(D6-I6),I6) -> 0.71379873 | AA6: =IF(V6=1,J6+$B$2*W6*(E6-J6),J6) -> 0.84502963 | AB6: =IF(V6=2,K6+$B$2*W6*(B6-K6),K6) -> 0.59262299 | AC6: =IF(V6=2,L6+$B$2*W6*(C6-L6),L6) -> 0.36896271 | AD6: =IF(V6=2,M6+$B$2*W6*(D6-M6),M6) -> 0.46829442 | AE6: =IF(V6=2,N6+$B$2*W6*(E6-N6),N6) -> 0.48332891 | AF6: =IF(V6=3,O6+$B$2*W6*(B6-O6),O6) -> 0.1424351 | AG6: =IF(V6=3,P6+$B$2*W6*(C6-P6),P6) -> 0.83224995 | AH6: =IF(V6=3,Q6+$B$2*W6*(D6-Q6),Q6) -> 0.17082942 | AI6: =IF(V6=3,R6+$B$2*W6*(E6-R6),R6) -> 0.12083822
A7: 3 | B7: 0.97222222 | C7: 0.12048193 | D7: 0.5 | E7: 1 | F7: 1 | G7: =X6 -> 0.90369743 | H7: =Y6 -> 0.067274647 | I7: =Z6 -> 0.71379873 | J7: =AA6 -> 0.84502963 | K7: =AB6 -> 0.59262299 | L7: =AC6 -> 0.36896271 | M7: =AD6 -> 0.46829442 | N7: =AE6 -> 0.48332891 | ... R7: =AI6 -> 0.12083822 | S7: =SQRT((B7-G7)^2+(C7-H7)^2+(D7-I7)^2+(E7-J7)^2) -> 0.27794312 | T7: =SQRT((B7-K7)^2+(C7-L7)^2+(D7-M7)^2+(E7-N7)^2) -> 0.6883259 | U7: =SQRT((B7-O7)^2+(C7-P7)^2+(D7-Q7)^2+(E7-R7)^2) -> 1.4409855 | V7: =IF(S7=MIN(S7:U7),1,IF(T7=MIN(S7:U7),2,3)) -> 1 | W7: =IF(V7=1,IF(F7=1,1,-1),IF(V7=2,IF(F7=2,1,-1),IF(F7=3,1,-1))) -> 1 | X7: =IF(V7=1,G7+$B$2*W7*(B7-G7),G7) -> 0.92219912 | Y7: =IF(V7=1,H7+$B$2*W7*(C7-H7),H7) -> 0.081640612 | Z7: =IF(V7=1,I7+$B$2*W7*(D7-I7),I7) -> 0.65607307 | AA7: =IF(V7=1,J7+$B$2*W7*(E7-J7),J7) -> 0.88687163 | AB7: =IF(V7=2,K7+$B$2*W7*(B7-K7),K7) -> 0.59262299 | AC7: =IF(V7=2,L7+$B$2*W7*(C7-L7),L7) -> 0.36896271 | AD7: =IF(V7=2,M7+$B$2*W7*(D7-M7),M7) -> 0.46829442 | AE7: =IF(V7=2,N7+$B$2*W7*(E7-N7),N7) -> 0.48332891 | AF7: =IF(V7=3,O7+$B$2*W7*(B7-O7),O7) -> 0.1424351 | AG7: =IF(V7=3,P7+$B$2*W7*(C7-P7),P7) -> 0.83224995 | AH7: =IF(V7=3,Q7+$B$2*W7*(D7-Q7),Q7) -> 0.17082942 | AI7: =IF(V7=3,R7+$B$2*W7*(E7-R7),R7) -> 0.12083822
A8: 4 | B8: 0.83333333 | C8: 0.084337349 | D8: 0.66666667 | E8: 0.8 | F8: 1 | G8: =X7 -> 0.92219912 | H8: =Y7 -> 0.081640612 | I8: =Z7 -> 0.65607307 | J8: =AA7 -> 0.88687163 | K8: =AB7 -> 0.59262299 | L8: =AC7 -> 0.36896271 | M8: =AD7 -> 0.46829442 | N8: =AE7 -> 0.48332891 | ... R8: =AI7 -> 0.12083822 | S8: =SQRT((B8-G8)^2+(C8-H8)^2+(D8-I8)^2+(E8-J8)^2) -> 0.12475298 | T8: =SQRT((B8-K8)^2+(C8-L8)^2+(D8-M8)^2+(E8-N8)^2) -> 0.52781171 | U8: =SQRT((B8-O8)^2+(C8-P8)^2+(D8-Q8)^2+(E8-R8)^2) -> 1.3205412 | V8: =IF(S8=MIN(S8:U8),1,IF(T8=MIN(S8:U8),2,3)) -> 1 | W8: =IF(V8=1,IF(F8=1,1,-1),IF(V8=2,IF(F8=2,1,-1),IF(F8=3,1,-1))) -> 1 | X8: =IF(V8=1,G8+$B$2*W8*(B8-G8),G8) -> 0.89820536 | Y8: =IF(V8=1,H8+$B$2*W8*(C8-H8),H8) -> 0.082368731 | Z8: =IF(V8=1,I8+$B$2*W8*(D8-I8),I8) -> 0.65893334 | AA8: =IF(V8=1,J8+$B$2*W8*(E8-J8),J8) -> 0.86341629 | AB8: =IF(V8=2,K8+$B$2*W8*(B8-K8),K8) -> 0.59262299 | AC8: =IF(V8=2,L8+$B$2*W8*(C8-L8),L8) -> 0.36896271 | AD8: =IF(V8=2,M8+$B$2*W8*(D8-M8),M8) -> 0.46829442 | AE8: =IF(V8=2,N8+$B$2*W8*(E8-N8),N8) -> 0.48332891 | AF8: =IF(V8=3,O8+$B$2*W8*(B8-O8),O8) -> 0.1424351 | AG8: =IF(V8=3,P8+$B$2*W8*(C8-P8),P8) -> 0.83224995 | AH8: =IF(V8=3,Q8+$B$2*W8*(D8-Q8),Q8) -> 0.17082942 | AI8: =IF(V8=3,R8+$B$2*W8*(E8-R8),R8) -> 0.12083822
A9: 5 | B9: 0.91666667 | C9: 0 | D9: 1 | E9: 0.9 | F9: 1 | G9: =X8 -> 0.89820536 | H9: =Y8 -> 0.082368731 | I9: =Z8 -> 0.65893334 | J9: =AA8 -> 0.86341629 | K9: =AB8 -> 0.59262299 | L9: =AC8 -> 0.36896271 | M9: =AD8 -> 0.46829442 | N9: =AE8 -> 0.48332891 | ... R9: =AI8 -> 0.12083822 | S9: =SQRT((B9-G9)^2+(C9-H9)^2+(D9-I9)^2+(E9-J9)^2) -> 0.35325665 | T9: =SQRT((B9-K9)^2+(C9-L9)^2+(D9-M9)^2+(E9-N9)^2) -> 0.83514275 | U9: =SQRT((B9-O9)^2+(C9-P9)^2+(D9-Q9)^2+(E9-R9)^2) -> 1.6083194 | V9: =IF(S9=MIN(S9:U9),1,IF(T9=MIN(S9:U9),2,3)) -> 1 | W9: =IF(V9=1,IF(F9=1,1,-1),IF(V9=2,IF(F9=2,1,-1),IF(F9=3,1,-1))) -> 1 | X9: =IF(V9=1,G9+$B$2*W9*(B9-G9),G9) -> 0.90318991 | Y9: =IF(V9=1,H9+$B$2*W9*(C9-H9),H9) -> 0.060129174 | Z9: =IF(V9=1,I9+$B$2*W9*(D9-I9),I9) -> 0.75102134 | AA9: =IF(V9=1,J9+$B$2*W9*(E9-J9),J9) -> 0.87329389 | AB9: =IF(V9=2,K9+$B$2*W9*(B9-K9),K9) -> 0.59262299 | AC9: =IF(V9=2,L9+$B$2*W9*(C9-L9),L9) -> 0.36896271 | AD9: =IF(V9=2,M9+$B$2*W9*(D9-M9),M9) -> 0.46829442 | AE9: =IF(V9=2,N9+$B$2*W9*(E9-N9),N9) -> 0.48332891 | AF9: =IF(V9=3,O9+$B$2*W9*(B9-O9),O9) -> 0.1424351 | AG9: =IF(V9=3,P9+$B$2*W9*(C9-P9),P9) -> 0.83224995 | AH9: =IF(V9=3,Q9+$B$2*W9*(D9-Q9),Q9) -> 0.17082942 | AI9: =IF(V9=3,R9+$B$2*W9*(E9-R9),R9) -> 0.12083822
A10: 6 | B10: 0.88888889 | C10: 0.15662651 | D10: 0.5 | E10: 0.8 | F10: 1 | G10: =X9 -> 0.90318991 | H10: =Y9 -> 0.060129174 | I10: =Z9 -> 0.75102134 | J10: =AA9 -> 0.87329389 | K10: =AB9 -> 0.59262299 | L10: =AC9 -> 0.36896271 | M10: =AD9 -> 0.46829442 | N10: =AE9 -> 0.48332891 | ... R10: =AI9 -> 0.12083822 | S10: =SQRT((B10-G10)^2+(C10-H10)^2+(D10-I10)^2+(E10-J10)^2) -> 0.27910565 | T10: =SQRT((B10-K10)^2+(C10-L10)^2+(D10-M10)^2+(E10-N10)^2) -> 0.48388632 | U10: =SQRT((B10-O10)^2+(C10-P10)^2+(D10-Q10)^2+(E10-R10)^2) -> 1.2582823 | V10: =IF(S10=MIN(S10:U10),1,IF(T10=MIN(S10:U10),2,3)) -> 1 | W10: =IF(V10=1,IF(F10=1,1,-1),IF(V10=2,IF(F10=2,1,-1),IF(F10=3,1,-1))) -> 1 | X10: =IF(V10=1,G10+$B$2*W10*(B10-G10),G10) -> 0.89932864 | Y10: =IF(V10=1,H10+$B$2*W10*(C10-H10),H10) -> 0.086183454 | Z10: =IF(V10=1,I10+$B$2*W10*(D10-I10),I10) -> 0.68324558 | AA10: =IF(V10=1,J10+$B$2*W10*(E10-J10),J10) -> 0.85350454 | AB10: =IF(V10=2,K10+$B$2*W10*(B10-K10),K10) -> 0.59262299 | AC10: =IF(V10=2,L10+$B$2*W10*(C10-L10),L10) -> 0.36896271 | AD10: =IF(V10=2,M10+$B$2*W10*(D10-M10),M10) -> 0.46829442 | AE10: =IF(V10=2,N10+$B$2*W10*(E10-N10),N10) -> 0.48332891 | AF10: =IF(V10=3,O10+$B$2*W10*(B10-O10),O10) -> 0.1424351 | AG10: =IF(V10=3,P10+$B$2*W10*(C10-P10),P10) -> 0.83224995 | AH10: =IF(V10=3,Q10+$B$2*W10*(D10-Q10),Q10) -> 0.17082942 | AI10: =IF(V10=3,R10+$B$2*W10*(E10-R10),R10) -> 0.12083822
A11: 7 | B11: 1 | C11: 0.072289157 | D11: 0.33333333 | E11: 1 | F11: 1 | G11: =X10 -> 0.89932864 | H11: =Y10 -> 0.086183454 | I11: =Z10 -> 0.68324558 | J11: =AA10 -> 0.85350454 | K11: =AB10 -> 0.59262299 | L11: =AC10 -> 0.36896271 | M11: =AD10 -> 0.46829442 | N11: =AE10 -> 0.48332891 | ... R11: =AI10 -> 0.12083822 | S11: =SQRT((B11-G11)^2+(C11-H11)^2+(D11-I11)^2+(E11-J11)^2) -> 0.3927178 | T11: =SQRT((B11-K11)^2+(C11-L11)^2+(D11-M11)^2+(E11-N11)^2) -> 0.73425796 | U11: =SQRT((B11-O11)^2+(C11-P11)^2+(D11-Q11)^2+(E11-R11)^2) -> 1.4533723 | V11: =IF(S11=MIN(S11:U11),1,IF(T11=MIN(S11:U11),2,3)) -> 1 | W11: =IF(V11=1,IF(F11=1,1,-1),IF(V11=2,IF(F11=2,1,-1),IF(F11=3,1,-1))) -> 1 | X11: =IF(V11=1,G11+$B$2*W11*(B11-G11),G11) -> 0.9265099 | Y11: =IF(V11=1,H11+$B$2*W11*(C11-H11),H11) -> 0.082431993 | Z11: =IF(V11=1,I11+$B$2*W11*(D11-I11),I11) -> 0.58876927 | AA11: =IF(V11=1,J11+$B$2*W11*(E11-J11),J11) -> 0.89305832 | AB11: =IF(V11=2,K11+$B$2*W11*(B11-K11),K11) -> 0.59262299 | AC11: =IF(V11=2,L11+$B$2*W11*(C11-L11),L11) -> 0.36896271 | AD11: =IF(V11=2,M11+$B$2*W11*(D11-M11),M11) -> 0.46829442 | AE11: =IF(V11=2,N11+$B$2*W11*(E11-N11),N11) -> 0.48332891 | AF11: =IF(V11=3,O11+$B$2*W11*(B11-O11),O11) -> 0.1424351 | AG11: =IF(V11=3,P11+$B$2*W11*(C11-P11),P11) -> 0.83224995 | AH11: =IF(V11=3,Q11+$B$2*W11*(D11-Q11),Q11) -> 0.17082942 | AI11: =IF(V11=3,R11+$B$2*W11*(E11-R11),R11) -> 0.12083822
A12: 8 | B12: 0.80555556 | C12: 0.048192771 | D12: 0.83333333 | E12: 0.7 | F12: 1 | G12: =X11 -> 0.9265099 | H12: =Y11 -> 0.082431993 | I12: =Z11 -> 0.58876927 | J12: =AA11 -> 0.89305832 | K12: =AB11 -> 0.59262299 | L12: =AC11 -> 0.36896271 | M12: =AD11 -> 0.46829442 | N12: =AE11 -> 0.48332891 | ... R12: =AI11 -> 0.12083822 | S12: =SQRT((B12-G12)^2+(C12-H12)^2+(D12-I12)^2+(E12-J12)^2) -> 0.33598418 | T12: =SQRT((B12-K12)^2+(C12-L12)^2+(D12-M12)^2+(E12-N12)^2) -> 0.5730911 | U12: =SQRT((B12-O12)^2+(C12-P12)^2+(D12-Q12)^2+(E12-R12)^2) -> 1.3523366 | V12: =IF(S12=MIN(S12:U12),1,IF(T12=MIN(S12:U12),2,3)) -> 1 | W12: =IF(V12=1,IF(F12=1,1,-1),IF(V12=2,IF(F12=2,1,-1),IF(F12=3,1,-1))) -> 1 | X12: =IF(V12=1,G12+$B$2*W12*(B12-G12),G12) -> 0.89385223 | Y12: =IF(V12=1,H12+$B$2*W12*(C12-H12),H12) -> 0.073187403 | Z12: =IF(V12=1,I12+$B$2*W12*(D12-I12),I12) -> 0.65480157 | AA12: =IF(V12=1,J12+$B$2*W12*(E12-J12),J12) -> 0.84093257 | AB12: =IF(V12=2,K12+$B$2*W12*(B12-K12),K12) -> 0.59262299 | AC12: =IF(V12=2,L12+$B$2*W12*(C12-L12),L12) -> 0.36896271 | AD12: =IF(V12=2,M12+$B$2*W12*(D12-M12),M12) -> 0.46829442 | AE12: =IF(V12=2,N12+$B$2*W12*(E12-N12),N12) -> 0.48332891 | AF12: =IF(V12=3,O12+$B$2*W12*(B12-O12),O12) -> 0.1424351 | AG12: =IF(V12=3,P12+$B$2*W12*(C12-P12),P12) -> 0.83224995 | AH12: =IF(V12=3,Q12+$B$2*W12*(D12-Q12),Q12) -> 0.17082942 | AI12: =IF(V12=3,R12+$B$2*W12*(E12-R12),R12) -> 0.12083822
A13: 9 | B13: 0.96111111 | C13: 0.13253012 | D13: 0.66666667 | E13: 0.9 | F13: 1 | G13: =X12 -> 0.89385223 | H13: =Y12 -> 0.073187403 | I13: =Z12 -> 0.65480157 | J13: =AA12 -> 0.84093257 | K13: =AB12 -> 0.59262299 | L13: =AC12 -> 0.36896271 | M13: =AD12 -> 0.46829442 | N13: =AE12 -> 0.48332891 | ... R13: =AI12 -> 0.12083822 | S13: =SQRT((B13-G13)^2+(C13-H13)^2+(D13-I13)^2+(E13-J13)^2) -> 0.10805118 | T13: =SQRT((B13-K13)^2+(C13-L13)^2+(D13-M13)^2+(E13-N13)^2) -> 0.63612123 | U13: =SQRT((B13-O13)^2+(C13-P13)^2+(D13-Q13)^2+(E13-R13)^2) -> 1.4187269 | V13: =IF(S13=MIN(S13:U13),1,IF(T13=MIN(S13:U13),2,3)) -> 1 | W13: =IF(V13=1,IF(F13=1,1,-1),IF(V13=2,IF(F13=2,1,-1),IF(F13=3,1,-1))) -> 1 | X13: =IF(V13=1,G13+$B$2*W13*(B13-G13),G13) -> 0.91201213 | Y13: =IF(V13=1,H13+$B$2*W13*(C13-H13),H13) -> 0.089209937 | Z13: =IF(V13=1,I13+$B$2*W13*(D13-I13),I13) -> 0.65800515 | AA13: =IF(V13=1,J13+$B$2*W13*(E13-J13),J13) -> 0.85688078 | AB13: =IF(V13=2,K13+$B$2*W13*(B13-K13),K13) -> 0.59262299 | AC13: =IF(V13=2,L13+$B$2*W13*(C13-L13),L13) -> 0.36896271 | AD13: =IF(V13=2,M13+$B$2*W13*(D13-M13),M13) -> 0.46829442 | AE13: =IF(V13=2,N13+$B$2*W13*(E13-N13),N13) -> 0.48332891 | AF13: =IF(V13=3,O13+$B$2*W13*(B13-O13),O13) -> 0.1424351 | AG13: =IF(V13=3,P13+$B$2*W13*(C13-P13),P13) -> 0.83224995 | AH13: =IF(V13=3,Q13+$B$2*W13*(D13-Q13),Q13) -> 0.17082942 | AI13: =IF(V13=3,R13+$B$2*W13*(E13-R13),R13) -> 0.12083822
A14: 10 | B14: 0.87222222 | C14: 0.012048193 | D14: 0.83333333 | E14: 0.8 | F14: 1 | G14: =X13 -> 0.91201213 | H14: =Y13 -> 0.089209937 | I14: =Z13 -> 0.65800515 | J14: =AA13 -> 0.85688078 | K14: =AB13 -> 0.59262299 | L14: =AC13 -> 0.36896271 | M14: =AD13 -> 0.46829442 | N14: =AE13 -> 0.48332891 | ... R14: =AI13 -> 0.12083822 | S14: =SQRT((B14-G14)^2+(C14-H14)^2+(D14-I14)^2+(E14-J14)^2) -> 0.20374633 | T14: =SQRT((B14-K14)^2+(C14-L14)^2+(D14-M14)^2+(E14-N14)^2) -> 0.66264447 | U14: =SQRT((B14-O14)^2+(C14-P14)^2+(D14-Q14)^2+(E14-R14)^2) -> 1.4510315 | V14: =IF(S14=MIN(S14:U14),1,IF(T14=MIN(S14:U14),2,3)) -> 1 | W14: =IF(V14=1,IF(F14=1,1,-1),IF(V14=2,IF(F14=2,1,-1),IF(F14=3,1,-1))) -> 1 | X14: =IF(V14=1,G14+$B$2*W14*(B14-G14),G14) -> 0.90126885 | Y14: =IF(V14=1,H14+$B$2*W14*(C14-H14),H14) -> 0.068376266 | Z14: =IF(V14=1,I14+$B$2*W14*(D14-I14),I14) -> 0.70534376 | AA14: =IF(V14=1,J14+$B$2*W14*(E14-J14),J14) -> 0.84152297 | AB14: =IF(V14=2,K14+$B$2*W14*(B14-K14),K14) -> 0.59262299 | AC14: =IF(V14=2,L14+$B$2*W14*(C14-L14),L14) -> 0.36896271 | AD14: =IF(V14=2,M14+$B$2*W14*(D14-M14),M14) -> 0.46829442 | AE14: =IF(V14=2,N14+$B$2*W14*(E14-N14),N14) -> 0.48332891 | AF14: =IF(V14=3,O14+$B$2*W14*(B14-O14),O14) -> 0.1424351 | AG14: =IF(V14=3,P14+$B$2*W14*(C14-P14),P14) -> 0.83224995 | AH14: =IF(V14=3,Q14+$B$2*W14*(D14-Q14),Q14) -> 0.17082942 | AI14: =IF(V14=3,R14+$B$2*W14*(E14-R14),R14) -> 0.12083822
A15: 11 | B15: 0.83888889 | C15: 0.10843373 | D15: 0.66666667 | E15: 0.7 | F15: 1 | G15: =X14 -> 0.90126885 | H15: =Y14 -> 0.068376266 | I15: =Z14 -> 0.70534376 | J15: =AA14 -> 0.84152297 | K15: =AB14 -> 0.59262299 | L15: =AC14 -> 0.36896271 | M15: =AD14 -> 0.46829442 | N15: =AE14 -> 0.48332891 | ... R15: =AI14 -> 0.12083822 | S15: =SQRT((B15-G15)^2+(C15-H15)^2+(D15-I15)^2+(E15-J15)^2) -> 0.16437922 | T15: =SQRT((B15-K15)^2+(C15-L15)^2+(D15-M15)^2+(E15-N15)^2) -> 0.46348695 | U15: =SQRT((B15-O15)^2+(C15-P15)^2+(D15-Q15)^2+(E15-R15)^2) -> 1.2610475 | V15: =IF(S15=MIN(S15:U15),1,IF(T15=MIN(S15:U15),2,3)) -> 1 | W15: =IF(V15=1,IF(F15=1,1,-1),IF(V15=2,IF(F15=2,1,-1),IF(F15=3,1,-1))) -> 1 | X15: =IF(V15=1,G15+$B$2*W15*(B15-G15),G15) -> 0.88442626 | Y15: =IF(V15=1,H15+$B$2*W15*(C15-H15),H15) -> 0.079191783 | Z15: =IF(V15=1,I15+$B$2*W15*(D15-I15),I15) -> 0.69490094 | AA15: =IF(V15=1,J15+$B$2*W15*(E15-J15),J15) -> 0.80331177 | AB15: =IF(V15=2,K15+$B$2*W15*(B15-K15),K15) -> 0.59262299 | AC15: =IF(V15=2,L15+$B$2*W15*(C15-L15),L15) -> 0.36896271 | AD15: =IF(V15=2,M15+$B$2*W15*(D15-M15),M15) -> 0.46829442 | AE15: =IF(V15=2,N15+$B$2*W15*(E15-N15),N15) -> 0.48332891 | AF15: =IF(V15=3,O15+$B$2*W15*(B15-O15),O15) -> 0.1424351 | AG15: =IF(V15=3,P15+$B$2*W15*(C15-P15),P15) -> 0.83224995 | AH15: =IF(V15=3,Q15+$B$2*W15*(D15-Q15),Q15) -> 0.17082942 | AI15: =IF(V15=3,R15+$B$2*W15*(E15-R15),R15) -> 0.12083822
A16: 12 | B16: 0.98333333 | C16: 0.060240964 | D16: 0.5 | E16: 1 | F16: 1 | G16: =X15 -> 0.88442626 | H16: =Y15 -> 0.079191783 | I16: =Z15 -> 0.69490094 | J16: =AA15 -> 0.80331177 | K16: =AB15 -> 0.59262299 | L16: =AC15 -> 0.36896271 | M16: =AD15 -> 0.46829442 | N16: =AE15 -> 0.48332891 | ... R16: =AI15 -> 0.12083822 | S16: =SQRT((B16-G16)^2+(C16-H16)^2+(D16-I16)^2+(E16-J16)^2) -> 0.2946428 | T16: =SQRT((B16-K16)^2+(C16-L16)^2+(D16-M16)^2+(E16-N16)^2) -> 0.71827429 | U16: =SQRT((B16-O16)^2+(C16-P16)^2+(D16-Q16)^2+(E16-R16)^2) -> 1.477967 | V16: =IF(S16=MIN(S16:U16),1,IF(T16=MIN(S16:U16),2,3)) -> 1 | W16: =IF(V16=1,IF(F16=1,1,-1),IF(V16=2,IF(F16=2,1,-1),IF(F16=3,1,-1))) -> 1 | X16: =IF(V16=1,G16+$B$2*W16*(B16-G16),G16) -> 0.91113117 | Y16: =IF(V16=1,H16+$B$2*W16*(C16-H16),H16) -> 0.074075062 | Z16: =IF(V16=1,I16+$B$2*W16*(D16-I16),I16) -> 0.64227769 | AA16: =IF(V16=1,J16+$B$2*W16*(E16-J16),J16) -> 0.85641759 | AB16: =IF(V16=2,K16+$B$2*W16*(B16-K16),K16) -> 0.59262299 | AC16: =IF(V16=2,L16+$B$2*W16*(C16-L16),L16) -> 0.36896271 | AD16: =IF(V16=2,M16+$B$2*W16*(D16-M16),M16) -> 0.46829442 | AE16: =IF(V16=2,N16+$B$2*W16*(E16-N16),N16) -> 0.48332891 | AF16: =IF(V16=3,O16+$B$2*W16*(B16-O16),O16) -> 0.1424351 | AG16: =IF(V16=3,P16+$B$2*W16*(C16-P16),P16) -> 0.83224995 | AH16: =IF(V16=3,Q16+$B$2*W16*(D16-Q16),Q16) -> 0.17082942 | AI16: =IF(V16=3,R16+$B$2*W16*(E16-R16),R16) -> 0.12083822
A17: 13 | B17: 0.90555556 | C17: 0.14457831 | D17: 0.66666667 | E17: 0.8 | F17: 1 | G17: =X16 -> 0.91113117 | H17: =Y16 -> 0.074075062 | I17: =Z16 -> 0.64227769 | J17: =AA16 -> 0.85641759 | K17: =AB16 -> 0.59262299 | L17: =AC16 -> 0.36896271 | M17: =AD16 -> 0.46829442 | N17: =AE16 -> 0.48332891 | ... R17: =AI16 -> 0.12083822 | S17: =SQRT((B17-G17)^2+(C17-H17)^2+(D17-I17)^2+(E17-J17)^2) -> 0.09369932 | T17: =SQRT((B17-K17)^2+(C17-L17)^2+(D17-M17)^2+(E17-N17)^2) -> 0.53656992 | U17: =SQRT((B17-O17)^2+(C17-P17)^2+(D17-Q17)^2+(E17-R17)^2) -> 1.3275392 | V17: =IF(S17=MIN(S17:U17),1,IF(T17=MIN(S17:U17),2,3)) -> 1 | W17: =IF(V17=1,IF(F17=1,1,-1),IF(V17=2,IF(F17=2,1,-1),IF(F17=3,1,-1))) -> 1 | X17: =IF(V17=1,G17+$B$2*W17*(B17-G17),G17) -> 0.90962576 | Y17: =IF(V17=1,H17+$B$2*W17*(C17-H17),H17) -> 0.09311094 | Z17: =IF(V17=1,I17+$B$2*W17*(D17-I17),I17) -> 0.64886271 | AA17: =IF(V17=1,J17+$B$2*W17*(E17-J17),J17) -> 0.84118484 | AB17: =IF(V17=2,K17+$B$2*W17*(B17-K17),K17) -> 0.59262299 | AC17: =IF(V17=2,L17+$B$2*W17*(C17-L17),L17) -> 0.36896271 | AD17: =IF(V17=2,M17+$B$2*W17*(D17-M17),M17) -> 0.46829442 | AE17: =IF(V17=2,N17+$B$2*W17*(E17-N17),N17) -> 0.48332891 | AF17: =IF(V17=3,O17+$B$2*W17*(B17-O17),O17) -> 0.1424351 | AG17: =IF(V17=3,P17+$B$2*W17*(C17-P17),P17) -> 0.83224995 | AH17: =IF(V17=3,Q17+$B$2*W17*(D17-Q17),Q17) -> 0.17082942 | AI17: =IF(V17=3,R17+$B$2*W17*(E17-R17),R17) -> 0.12083822
... A54: 50 | B54: 0 | C54: 1 | D54: 0.16666667 | E54: 0 | F54: 3 | G54: =X53 -> 0.91015842 | H54: =Y53 -> 0.08486998 | I54: =Z53 -> 0.67560269 | J54: =AA53 -> 0.84723093 | K54: =AB53 -> 0.59351242 | L54: =AC53 -> 0.36720259 | M54: =AD53 -> 0.4731069 | N54: =AE53 -> 0.48588205 | ... R54: =AI53 -> 0.17259741 | S54: =SQRT((B54-G54)^2+(C54-H54)^2+(D54-I54)^2+(E54-J54)^2) -> 1.6256283 | T54: =SQRT((B54-K54)^2+(C54-L54)^2+(D54-M54)^2+(E54-N54)^2) -> 1.0405174 | U54: =SQRT((B54-O54)^2+(C54-P54)^2+(D54-Q54)^2+(E54-R54)^2) -> 0.35556361 | V54: =IF(S54=MIN(S54:U54),1,IF(T54=MIN(S54:U54),2,3)) -> 3 | W54: =IF(V54=1,IF(F54=1,1,-1),IF(V54=2,IF(F54=2,1,-1),IF(F54=3,1,-1))) -> 1 | X54: =IF(V54=1,G54+$B$2*W54*(B54-G54),G54) -> 0.91015842 | Y54: =IF(V54=1,H54+$B$2*W54*(C54-H54),H54) -> 0.08486998 | Z54: =IF(V54=1,I54+$B$2*W54*(D54-I54),I54) -> 0.67560269 | AA54: =IF(V54=1,J54+$B$2*W54*(E54-J54),J54) -> 0.84723093 | AB54: =IF(V54=2,K54+$B$2*W54*(B54-K54),K54) -> 0.59351242 | AC54: =IF(V54=2,L54+$B$2*W54*(C54-L54),L54) -> 0.36720259 | AD54: =IF(V54=2,M54+$B$2*W54*(D54-M54),M54) -> 0.4731069 | AE54: =IF(V54=2,N54+$B$2*W54*(E54-N54),N54) -> 0.48588205 | AF54: =IF(V54=3,O54+$B$2*W54*(B54-O54),O54) -> 0.14691827 | AG54: =IF(V54=3,P54+$B$2*W54*(C54-P54),P54) -> 0.82706265 | AH54: =IF(V54=3,Q54+$B$2*W54*(D54-Q54),Q54) -> 0.16886037 | AI54: =IF(V54=3,R54+$B$2*W54*(E54-R54),R54) -> 0.12599611

Sheet Manual_Epoch3
A1: Perhitungan Manual LVQ - Epoch 3 (50 data)
A2: Alpha (α) | B2: 0.243
A4: ID | B4: X1 | C4: X2 | D4: X3 | E4: X4 | F4: Target | G4: W1_x1 | H4: W1_x2 | I4: W1_x3 | J4: W1_x4 | K4: W2_x1 | L4: W2_x2 | M4: W2_x3 | N4: W2_x4 | O4: W3_x1 | P4: W3_x2 | Q4: W3_x3 | R4: W3_x4 | S4: d_W1 | T4: d_W2 | U4: d_W3 | V4: Winner | W4: Sign(+1/-1) | X4: W1_new_x1 | Y4: W1_new_x2 | Z4: W1_new_x3 | AA4: W1_new_x4 | AB4: W2_new_x1 | AC4: W2_new_x2 | AD4: W2_new_x3 | AE4: W2_new_x4 | AF4: W3_new_x1 | AG4: W3_new_x2 | AH4: W3_new_x3 | AI4: W3_new_x4
A5: 1 | B5: 0.94444444 | C5: 0.060240964 | D5: 0.66666667 | E5: 0.9 | F5: 1 | G5: =Manual_Epoch2!X54 -> 0.91015842 | H5: =Manual_Epoch2!Y54 -> 0.08486998 | I5: =Manual_Epoch2!Z54 -> 0.67560269 | J5: =Manual_Epoch2!AA54 -> 0.84723093 | K5: =Manual_Epoch2!AB54 -> 0.59351242 | L5: =Manual_Epoch2!AC54 -> 0.36720259 | M5: =Manual_Epoch2!AD54 -> 0.4731069 | N5: =Manual_Epoch2!AE54 -> 0.48588205 | ... R5: =Manual_Epoch2!AI54 -> 0.12599611 | S5: =SQRT((B5-G5)^2+(C5-H5)^2+(D5-I5)^2+(E5-J5)^2) -> 0.068165585 | T5: =SQRT((B5-K5)^2+(C5-L5)^2+(D5-M5)^2+(E5-N5)^2) -> 0.65294547 | U5: =SQRT((B5-O5)^2+(C5-P5)^2+(D5-Q5)^2+(E5-R5)^2) -> 1.4390819 | V5: =IF(S5=MIN(S5:U5),1,IF(T5=MIN(S5:U5),2,3)) -> 1 | W5: =IF(V5=1,IF(F5=1,1,-1),IF(V5=2,IF(F5=2,1,-1),IF(F5=3,1,-1))) -> 1 | X5: =IF(V5=1,G5+$B$2*W5*(B5-G5),G5) -> 0.91848993 | Y5: =IF(V5=1,H5+$B$2*W5*(C5-H5),H5) -> 0.078885129 | Z5: =IF(V5=1,I5+$B$2*W5*(D5-I5),I5) -> 0.67343123 | AA5: =IF(V5=1,J5+$B$2*W5*(E5-J5),J5) -> 0.86005381 | AB5: =IF(V5=2,K5+$B$2*W5*(B5-K5),K5) -> 0.59351242 | AC5: =IF(V5=2,L5+$B$2*W5*(C5-L5),L5) -> 0.36720259 | AD5: =IF(V5=2,M5+$B$2*W5*(D5-M5),M5) -> 0.4731069 | AE5: =IF(V5=2,N5+$B$2*W5*(E5-N5),N5) -> 0.48588205 | AF5: =IF(V5=3,O5+$B$2*W5*(B5-O5),O5) -> 0.14691827 | AG5: =IF(V5=3,P5+$B$2*W5*(C5-P5),P5) -> 0.82706265 | AH5: =IF(V5=3,Q5+$B$2*W5*(D5-Q5),Q5) -> 0.16886037 | AI5: =IF(V5=3,R5+$B$2*W5*(E5-R5),R5) -> 0.12599611
A6: 2 | B6: 0.86111111 | C6: 0.036144578 | D6: 0.83333333 | E6: 0.8 | F6: 1 | G6: =X5 -> 0.91848993 | H6: =Y5 -> 0.078885129 | I6: =Z5 -> 0.67343123 | J6: =AA5 -> 0.86005381 | K6: =AB5 -> 0.59351242 | L6: =AC5 -> 0.36720259 | M6: =AD5 -> 0.4731069 | N6: =AE5 -> 0.48588205 | ... R6: =AI5 -> 0.12599611 | S6: =SQRT((B6-G6)^2+(C6-H6)^2+(D6-I6)^2+(E6-J6)^2) -> 0.185187 | T6: =SQRT((B6-K6)^2+(C6-L6)^2+(D6-M6)^2+(E6-N6)^2) -> 0.64003253 | U6: =SQRT((B6-O6)^2+(C6-P6)^2+(D6-Q6)^2+(E6-R6)^2) -> 1.4252819 | V6: =IF(S6=MIN(S6:U6),1,IF(T6=MIN(S6:U6),2,3)) -> 1 | W6: =IF(V6=1,IF(F6=1,1,-1),IF(V6=2,IF(F6=2,1,-1),IF(F6=3,1,-1))) -> 1 | X6: =IF(V6=1,G6+$B$2*W6*(B6-G6),G6) -> 0.90454687 | Y6: =IF(V6=1,H6+$B$2*W6*(C6-H6),H6) -> 0.068499175 | Z6: =IF(V6=1,I6+$B$2*W6*(D6-I6),I6) -> 0.71228744 | AA6: =IF(V6=1,J6+$B$2*W6*(E6-J6),J6) -> 0.84546074 | AB6: =IF(V6=2,K6+$B$2*W6*(B6-K6),K6) -> 0.59351242 | AC6: =IF(V6=2,L6+$B$2*W6*(C6-L6),L6) -> 0.36720259 | AD6: =IF(V6=2,M6+$B$2*W6*(D6-M6),M6) -> 0.4731069 | AE6: =IF(V6=2,N6+$B$2*W6*(E6-N6),N6) -> 0.48588205 | AF6: =IF(V6=3,O6+$B$2*W6*(B6-O6),O6) -> 0.14691827 | AG6: =IF(V6=3,P6+$B$2*W6*(C6-P6),P6) -> 0.82706265 | AH6: =IF(V6=3,Q6+$B$2*W6*(D6-Q6),Q6) -> 0.16886037 | AI6: =IF(V6=3,R6+$B$2*W6*(E6-R6),R6) -> 0.12599611
A7: 3 | B7: 0.97222222 | C7: 0.12048193 | D7: 0.5 | E7: 1 | F7: 1 | G7: =X6 -> 0.90454687 | H7: =Y6 -> 0.068499175 | I7: =Z6 -> 0.71228744 | J7: =AA6 -> 0.84546074 | K7: =AB6 -> 0.59351242 | L7: =AC6 -> 0.36720259 | M7: =AD6 -> 0.4731069 | N7: =AE6 -> 0.48588205 | ... R7: =AI6 -> 0.12599611 | S7: =SQRT((B7-G7)^2+(C7-H7)^2+(D7-I7)^2+(E7-J7)^2) -> 0.27609872 | T7: =SQRT((B7-K7)^2+(C7-L7)^2+(D7-M7)^2+(E7-N7)^2) -> 0.68507861 | U7: =SQRT((B7-O7)^2+(C7-P7)^2+(D7-Q7)^2+(E7-R7)^2) -> 1.4331501 | V7: =IF(S7=MIN(S7:U7),1,IF(T7=MIN(S7:U7),2,3)) -> 1 | W7: =IF(V7=1,IF(F7=1,1,-1),IF(V7=2,IF(F7=2,1,-1),IF(F7=3,1,-1))) -> 1 | X7: =IF(V7=1,G7+$B$2*W7*(B7-G7),G7) -> 0.92099198 | Y7: =IF(V7=1,H7+$B$2*W7*(C7-H7),H7) -> 0.081130984 | Z7: =IF(V7=1,I7+$B$2*W7*(D7-I7),I7) -> 0.6607016 | AA7: =IF(V7=1,J7+$B$2*W7*(E7-J7),J7) -> 0.88301378 | AB7: =IF(V7=2,K7+$B$2*W7*(B7-K7),K7) -> 0.59351242 | AC7: =IF(V7=2,L7+$B$2*W7*(C7-L7),L7) -> 0.36720259 | AD7: =IF(V7=2,M7+$B$2*W7*(D7-M7),M7) -> 0.4731069 | AE7: =IF(V7=2,N7+$B$2*W7*(E7-N7),N7) -> 0.48588205 | AF7: =IF(V7=3,O7+$B$2*W7*(B7-O7),O7) -> 0.14691827 | AG7: =IF(V7=3,P7+$B$2*W7*(C7-P7),P7) -> 0.82706265 | AH7: =IF(V7=3,Q7+$B$2*W7*(D7-Q7),Q7) -> 0.16886037 | AI7: =IF(V7=3,R7+$B$2*W7*(E7-R7),R7) -> 0.12599611
A8: 4 | B8: 0.83333333 | C8: 0.084337349 | D8: 0.66666667 | E8: 0.8 | F8: 1 | G8: =X7 -> 0.92099198 | H8: =Y7 -> 0.081130984 | I8: =Z7 -> 0.6607016 | J8: =AA7 -> 0.88301378 | K8: =AB7 -> 0.59351242 | L8: =AC7 -> 0.36720259 | M8: =AD7 -> 0.4731069 | N8: =AE7 -> 0.48588205 | ... R8: =AI7 -> 0.12599611 | S8: =SQRT((B8-G8)^2+(C8-H8)^2+(D8-I8)^2+(E8-J8)^2) -> 0.12091811 | T8: =SQRT((B8-K8)^2+(C8-L8)^2+(D8-M8)^2+(E8-N8)^2) -> 0.52312741 | U8: =SQRT((B8-O8)^2+(C8-P8)^2+(D8-Q8)^2+(E8-R8)^2) -> 1.3133541 | V8: =IF(S8=MIN(S8:U8),1,IF(T8=MIN(S8:U8),2,3)) -> 1 | W8: =IF(V8=1,IF(F8=1,1,-1),IF(V8=2,IF(F8=2,1,-1),IF(F8=3,1,-1))) -> 1 | X8: =IF(V8=1,G8+$B$2*W8*(B8-G8),G8) -> 0.89969093 | Y8: =IF(V8=1,H8+$B$2*W8*(C8-H8),H8) -> 0.081910131 | Z8: =IF(V8=1,I8+$B$2*W8*(D8-I8),I8) -> 0.66215111 | AA8: =IF(V8=1,J8+$B$2*W8*(E8-J8),J8) -> 0.86284143 | AB8: =IF(V8=2,K8+$B$2*W8*(B8-K8),K8) -> 0.59351242 | AC8: =IF(V8=2,L8+$B$2*W8*(C8-L8),L8) -> 0.36720259 | AD8: =IF(V8=2,M8+$B$2*W8*(D8-M8),M8) -> 0.4731069 | AE8: =IF(V8=2,N8+$B$2*W8*(E8-N8),N8) -> 0.48588205 | AF8: =IF(V8=3,O8+$B$2*W8*(B8-O8),O8) -> 0.14691827 | AG8: =IF(V8=3,P8+$B$2*W8*(C8-P8),P8) -> 0.82706265 | AH8: =IF(V8=3,Q8+$B$2*W8*(D8-Q8),Q8) -> 0.16886037 | AI8: =IF(V8=3,R8+$B$2*W8*(E8-R8),R8) -> 0.12599611
A9: 5 | B9: 0.91666667 | C9: 0 | D9: 1 | E9: 0.9 | F9: 1 | G9: =X8 -> 0.89969093 | H9: =Y8 -> 0.081910131 | I9: =Z8 -> 0.66215111 | J9: =AA8 -> 0.86284143 | K9: =AB8 -> 0.59351242 | L9: =AC8 -> 0.36720259 | M9: =AD8 -> 0.4731069 | N9: =AE8 -> 0.48588205 | ... R9: =AI8 -> 0.12599611 | S9: =SQRT((B9-G9)^2+(C9-H9)^2+(D9-I9)^2+(E9-J9)^2) -> 0.35002868 | T9: =SQRT((B9-K9)^2+(C9-L9)^2+(D9-M9)^2+(E9-N9)^2) -> 0.82968454 | U9: =SQRT((B9-O9)^2+(C9-P9)^2+(D9-Q9)^2+(E9-R9)^2) -> 1.6020051 | V9: =IF(S9=MIN(S9:U9),1,IF(T9=MIN(S9:U9),2,3)) -> 1 | W9: =IF(V9=1,IF(F9=1,1,-1),IF(V9=2,IF(F9=2,1,-1),IF(F9=3,1,-1))) -> 1 | X9: =IF(V9=1,G9+$B$2*W9*(B9-G9),G9) -> 0.90381604 | Y9: =IF(V9=1,H9+$B$2*W9*(C9-H9),H9) -> 0.062005969 | Z9: =IF(V9=1,I9+$B$2*W9*(D9-I9),I9) -> 0.74424839 | AA9: =IF(V9=1,J9+$B$2*W9*(E9-J9),J9) -> 0.87187096 | AB9: =IF(V9=2,K9+$B$2*W9*(B9-K9),K9) -> 0.59351242 | AC9: =IF(V9=2,L9+$B$2*W9*(C9-L9),L9) -> 0.36720259 | AD9: =IF(V9=2,M9+$B$2*W9*(D9-M9),M9) -> 0.4731069 | AE9: =IF(V9=2,N9+$B$2*W9*(E9-N9),N9) -> 0.48588205 | AF9: =IF(V9=3,O9+$B$2*W9*(B9-O9),O9) -> 0.14691827 | AG9: =IF(V9=3,P9+$B$2*W9*(C9-P9),P9) -> 0.82706265 | AH9: =IF(V9=3,Q9+$B$2*W9*(D9-Q9),Q9) -> 0.16886037 | AI9: =IF(V9=3,R9+$B$2*W9*(E9-R9),R9) -> 0.12599611
A10: 6 | B10: 0.88888889 | C10: 0.15662651 | D10: 0.5 | E10: 0.8 | F10: 1 | G10: =X9 -> 0.90381604 | H10: =Y9 -> 0.062005969 | I10: =Z9 -> 0.74424839 | J10: =AA9 -> 0.87187096 | K10: =AB9 -> 0.59351242 | L10: =AC9 -> 0.36720259 | M10: =AD9 -> 0.4731069 | N10: =AE9 -> 0.48588205 | ... R10: =AI9 -> 0.12599611 | S10: =SQRT((B10-G10)^2+(C10-H10)^2+(D10-I10)^2+(E10-J10)^2) -> 0.27202679 | T10: =SQRT((B10-K10)^2+(C10-L10)^2+(D10-M10)^2+(E10-N10)^2) -> 0.48060677 | U10: =SQRT((B10-O10)^2+(C10-P10)^2+(D10-Q10)^2+(E10-R10)^2) -> 1.2505758 | V10: =IF(S10=MIN(S10:U10),1,IF(T10=MIN(S10:U10),2,3)) -> 1 | W10: =IF(V10=1,IF(F10=1,1,-1),IF(V10=2,IF(F10=2,1,-1),IF(F10=3,1,-1))) -> 1 | X10: =IF(V10=1,G10+$B$2*W10*(B10-G10),G10) -> 0.90018874 | Y10: =IF(V10=1,H10+$B$2*W10*(C10-H10),H10) -> 0.084998759 | Z10: =IF(V10=1,I10+$B$2*W10*(D10-I10),I10) -> 0.68489603 | AA10: =IF(V10=1,J10+$B$2*W10*(E10-J10),J10) -> 0.85440632 | AB10: =IF(V10=2,K10+$B$2*W10*(B10-K10),K10) -> 0.59351242 | AC10: =IF(V10=2,L10+$B$2*W10*(C10-L10),L10) -> 0.36720259 | AD10: =IF(V10=2,M10+$B$2*W10*(D10-M10),M10) -> 0.4731069 | AE10: =IF(V10=2,N10+$B$2*W10*(E10-N10),N10) -> 0.48588205 | AF10: =IF(V10=3,O10+$B$2*W10*(B10-O10),O10) -> 0.14691827 | AG10: =IF(V10=3,P10+$B$2*W10*(C10-P10),P10) -> 0.82706265 | AH10: =IF(V10=3,Q10+$B$2*W10*(D10-Q10),Q10) -> 0.16886037 | AI10: =IF(V10=3,R10+$B$2*W10*(E10-R10),R10) -> 0.12599611
A11: 7 | B11: 1 | C11: 0.072289157 | D11: 0.33333333 | E11: 1 | F11: 1 | G11: =X10 -> 0.90018874 | H11: =Y10 -> 0.084998759 | I11: =Z10 -> 0.68489603 | J11: =AA10 -> 0.85440632 | K11: =AB10 -> 0.59351242 | L11: =AC10 -> 0.36720259 | M11: =AD10 -> 0.4731069 | N11: =AE10 -> 0.48588205 | ... R11: =AI10 -> 0.12599611 | S11: =SQRT((B11-G11)^2+(C11-H11)^2+(D11-I11)^2+(E11-J11)^2) -> 0.39359582 | T11: =SQRT((B11-K11)^2+(C11-L11)^2+(D11-M11)^2+(E11-N11)^2) -> 0.73216118 | U11: =SQRT((B11-O11)^2+(C11-P11)^2+(D11-Q11)^2+(E11-R11)^2) -> 1.4451179 | V11: =IF(S11=MIN(S11:U11),1,IF(T11=MIN(S11:U11),2,3)) -> 1 | W11: =IF(V11=1,IF(F11=1,1,-1),IF(V11=2,IF(F11=2,1,-1),IF(F11=3,1,-1))) -> 1 | X11: =IF(V11=1,G11+$B$2*W11*(B11-G11),G11) -> 0.92444288 | Y11: =IF(V11=1,H11+$B$2*W11*(C11-H11),H11) -> 0.081910326 | Z11: =IF(V11=1,I11+$B$2*W11*(D11-I11),I11) -> 0.59946629 | AA11: =IF(V11=1,J11+$B$2*W11*(E11-J11),J11) -> 0.88978558 | AB11: =IF(V11=2,K11+$B$2*W11*(B11-K11),K11) -> 0.59351242 | AC11: =IF(V11=2,L11+$B$2*W11*(C11-L11),L11) -> 0.36720259 | AD11: =IF(V11=2,M11+$B$2*W11*(D11-M11),M11) -> 0.4731069 | AE11: =IF(V11=2,N11+$B$2*W11*(E11-N11),N11) -> 0.48588205 | AF11: =IF(V11=3,O11+$B$2*W11*(B11-O11),O11) -> 0.14691827 | AG11: =IF(V11=3,P11+$B$2*W11*(C11-P11),P11) -> 0.82706265 | AH11: =IF(V11=3,Q11+$B$2*W11*(D11-Q11),Q11) -> 0.16886037 | AI11: =IF(V11=3,R11+$B$2*W11*(E11-R11),R11) -> 0.12599611
A12: 8 | B12: 0.80555556 | C12: 0.048192771 | D12: 0.83333333 | E12: 0.7 | F12: 1 | G12: =X11 -> 0.92444288 | H12: =Y11 -> 0.081910326 | I12: =Z11 -> 0.59946629 | J12: =AA11 -> 0.88978558 | K12: =AB11 -> 0.59351242 | L12: =AC11 -> 0.36720259 | M12: =AD11 -> 0.4731069 | N12: =AE11 -> 0.48588205 | ... R12: =AI11 -> 0.12599611 | S12: =SQRT((B12-G12)^2+(C12-H12)^2+(D12-I12)^2+(E12-J12)^2) -> 0.32555096 | T12: =SQRT((B12-K12)^2+(C12-L12)^2+(D12-M12)^2+(E12-N12)^2) -> 0.56774919 | U12: =SQRT((B12-O12)^2+(C12-P12)^2+(D12-Q12)^2+(E12-R12)^2) -> 1.3458998 | V12: =IF(S12=MIN(S12:U12),1,IF(T12=MIN(S12:U12),2,3)) -> 1 | W12: =IF(V12=1,IF(F12=1,1,-1),IF(V12=2,IF(F12=2,1,-1),IF(F12=3,1,-1))) -> 1 | X12: =IF(V12=1,G12+$B$2*W12*(B12-G12),G12) -> 0.89555326 | Y12: =IF(V12=1,H12+$B$2*W12*(C12-H12),H12) -> 0.07371696 | Z12: =IF(V12=1,I12+$B$2*W12*(D12-I12),I12) -> 0.65629599 | AA12: =IF(V12=1,J12+$B$2*W12*(E12-J12),J12) -> 0.84366769 | AB12: =IF(V12=2,K12+$B$2*W12*(B12-K12),K12) -> 0.59351242 | AC12: =IF(V12=2,L12+$B$2*W12*(C12-L12),L12) -> 0.36720259 | AD12: =IF(V12=2,M12+$B$2*W12*(D12-M12),M12) -> 0.4731069 | AE12: =IF(V12=2,N12+$B$2*W12*(E12-N12),N12) -> 0.48588205 | AF12: =IF(V12=3,O12+$B$2*W12*(B12-O12),O12) -> 0.14691827 | AG12: =IF(V12=3,P12+$B$2*W12*(C12-P12),P12) -> 0.82706265 | AH12: =IF(V12=3,Q12+$B$2*W12*(D12-Q12),Q12) -> 0.16886037 | AI12: =IF(V12=3,R12+$B$2*W12*(E12-R12),R12) -> 0.12599611
A13: 9 | B13: 0.96111111 | C13: 0.13253012 | D13: 0.66666667 | E13: 0.9 | F13: 1 | G13: =X12 -> 0.89555326 | H13: =Y12 -> 0.07371696 | I13: =Z12 -> 0.65629599 | J13: =AA12 -> 0.84366769 | K13: =AB12 -> 0.59351242 | L13: =AC12 -> 0.36720259 | M13: =AD12 -> 0.4731069 | N13: =AE12 -> 0.48588205 | ... R13: =AI12 -> 0.12599611 | S13: =SQRT((B13-G13)^2+(C13-H13)^2+(D13-I13)^2+(E13-J13)^2) -> 0.10506046 | T13: =SQRT((B13-K13)^2+(C13-L13)^2+(D13-M13)^2+(E13-N13)^2) -> 0.63179033 | U13: =SQRT((B13-O13)^2+(C13-P13)^2+(D13-Q13)^2+(E13-R13)^2) -> 1.4114456 | V13: =IF(S13=MIN(S13:U13),1,IF(T13=MIN(S13:U13),2,3)) -> 1 | W13: =IF(V13=1,IF(F13=1,1,-1),IF(V13=2,IF(F13=2,1,-1),IF(F13=3,1,-1))) -> 1 | X13: =IF(V13=1,G13+$B$2*W13*(B13-G13),G13) -> 0.91148382 | Y13: =IF(V13=1,H13+$B$2*W13*(C13-H13),H13) -> 0.088008558 | Z13: =IF(V13=1,I13+$B$2*W13*(D13-I13),I13) -> 0.65881606 | AA13: =IF(V13=1,J13+$B$2*W13*(E13-J13),J13) -> 0.85735644 | AB13: =IF(V13=2,K13+$B$2*W13*(B13-K13),K13) -> 0.59351242 | AC13: =IF(V13=2,L13+$B$2*W13*(C13-L13),L13) -> 0.36720259 | AD13: =IF(V13=2,M13+$B$2*W13*(D13-M13),M13) -> 0.4731069 | AE13: =IF(V13=2,N13+$B$2*W13*(E13-N13),N13) -> 0.48588205 | AF13: =IF(V13=3,O13+$B$2*W13*(B13-O13),O13) -> 0.14691827 | AG13: =IF(V13=3,P13+$B$2*W13*(C13-P13),P13) -> 0.82706265 | AH13: =IF(V13=3,Q13+$B$2*W13*(D13-Q13),Q13) -> 0.16886037 | AI13: =IF(V13=3,R13+$B$2*W13*(E13-R13),R13) -> 0.12599611
A14: 10 | B14: 0.87222222 | C14: 0.012048193 | D14: 0.83333333 | E14: 0.8 | F14: 1 | G14: =X13 -> 0.91148382 | H14: =Y13 -> 0.088008558 | I14: =Z13 -> 0.65881606 | J14: =AA13 -> 0.85735644 | K14: =AB13 -> 0.59351242 | L14: =AC13 -> 0.36720259 | M14: =AD13 -> 0.4731069 | N14: =AE13 -> 0.48588205 | ... R14: =AI13 -> 0.12599611 | S14: =SQRT((B14-G14)^2+(C14-H14)^2+(D14-I14)^2+(E14-J14)^2) -> 0.20262648 | T14: =SQRT((B14-K14)^2+(C14-L14)^2+(D14-M14)^2+(E14-N14)^2) -> 0.65745492 | U14: =SQRT((B14-O14)^2+(C14-P14)^2+(D14-Q14)^2+(E14-R14)^2) -> 1.4443407 | V14: =IF(S14=MIN(S14:U14),1,IF(T14=MIN(S14:U14),2,3)) -> 1 | W14: =IF(V14=1,IF(F14=1,1,-1),IF(V14=2,IF(F14=2,1,-1),IF(F14=3,1,-1))) -> 1 | X14: =IF(V14=1,G14+$B$2*W14*(B14-G14),G14) -> 0.90194325 | Y14: =IF(V14=1,H14+$B$2*W14*(C14-H14),H14) -> 0.069550189 | Z14: =IF(V14=1,I14+$B$2*W14*(D14-I14),I14) -> 0.70122376 | AA14: =IF(V14=1,J14+$B$2*W14*(E14-J14),J14) -> 0.84341882 | AB14: =IF(V14=2,K14+$B$2*W14*(B14-K14),K14) -> 0.59351242 | AC14: =IF(V14=2,L14+$B$2*W14*(C14-L14),L14) -> 0.36720259 | AD14: =IF(V14=2,M14+$B$2*W14*(D14-M14),M14) -> 0.4731069 | AE14: =IF(V14=2,N14+$B$2*W14*(E14-N14),N14) -> 0.48588205 | AF14: =IF(V14=3,O14+$B$2*W14*(B14-O14),O14) -> 0.14691827 | AG14: =IF(V14=3,P14+$B$2*W14*(C14-P14),P14) -> 0.82706265 | AH14: =IF(V14=3,Q14+$B$2*W14*(D14-Q14),Q14) -> 0.16886037 | AI14: =IF(V14=3,R14+$B$2*W14*(E14-R14),R14) -> 0.12599611
A15: 11 | B15: 0.83888889 | C15: 0.10843373 | D15: 0.66666667 | E15: 0.7 | F15: 1 | G15: =X14 -> 0.90194325 | H15: =Y14 -> 0.069550189 | I15: =Z14 -> 0.70122376 | J15: =AA14 -> 0.84341882 | K15: =AB14 -> 0.59351242 | L15: =AC14 -> 0.36720259 | M15: =AD14 -> 0.4731069 | N15: =AE14 -> 0.48588205 | ... R15: =AI14 -> 0.12599611 | S15: =SQRT((B15-G15)^2+(C15-H15)^2+(D15-I15)^2+(E15-J15)^2) -> 0.16507857 | T15: =SQRT((B15-K15)^2+(C15-L15)^2+(D15-M15)^2+(E15-N15)^2) -> 0.45878406 | U15: =SQRT((B15-O15)^2+(C15-P15)^2+(D15-Q15)^2+(E15-R15)^2) -> 1.2540105 | V15: =IF(S15=MIN(S15:U15),1,IF(T15=MIN(S15:U15),2,3)) -> 1 | W15: =IF(V15=1,IF(F15=1,1,-1),IF(V15=2,IF(F15=2,1,-1),IF(F15=3,1,-1))) -> 1 | X15: =IF(V15=1,G15+$B$2*W15*(B15-G15),G15) -> 0.88662104 | Y15: =IF(V15=1,H15+$B$2*W15*(C15-H15),H15) -> 0.078998891 | Z15: =IF(V15=1,I15+$B$2*W15*(D15-I15),I15) -> 0.69282638 | AA15: =IF(V15=1,J15+$B$2*W15*(E15-J15),J15) -> 0.80856805 | AB15: =IF(V15=2,K15+$B$2*W15*(B15-K15),K15) -> 0.59351242 | AC15: =IF(V15=2,L15+$B$2*W15*(C15-L15),L15) -> 0.36720259 | AD15: =IF(V15=2,M15+$B$2*W15*(D15-M15),M15) -> 0.4731069 | AE15: =IF(V15=2,N15+$B$2*W15*(E15-N15),N15) -> 0.48588205 | AF15: =IF(V15=3,O15+$B$2*W15*(B15-O15),O15) -> 0.14691827 | AG15: =IF(V15=3,P15+$B$2*W15*(C15-P15),P15) -> 0.82706265 | AH15: =IF(V15=3,Q15+$B$2*W15*(D15-Q15),Q15) -> 0.16886037 | AI15: =IF(V15=3,R15+$B$2*W15*(E15-R15),R15) -> 0.12599611
A16: 12 | B16: 0.98333333 | C16: 0.060240964 | D16: 0.5 | E16: 1 | F16: 1 | G16: =X15 -> 0.88662104 | H16: =Y15 -> 0.078998891 | I16: =Z15 -> 0.69282638 | J16: =AA15 -> 0.80856805 | K16: =AB15 -> 0.59351242 | L16: =AC15 -> 0.36720259 | M16: =AD15 -> 0.4731069 | N16: =AE15 -> 0.48588205 | ... R16: =AI15 -> 0.12599611 | S16: =SQRT((B16-G16)^2+(C16-H16)^2+(D16-I16)^2+(E16-J16)^2) -> 0.28902134 | T16: =SQRT((B16-K16)^2+(C16-L16)^2+(D16-M16)^2+(E16-N16)^2) -> 0.7150009 | U16: =SQRT((B16-O16)^2+(C16-P16)^2+(D16-Q16)^2+(E16-R16)^2) -> 1.4700823 | V16: =IF(S16=MIN(S16:U16),1,IF(T16=MIN(S16:U16),2,3)) -> 1 | W16: =IF(V16=1,IF(F16=1,1,-1),IF(V16=2,IF(F16=2,1,-1),IF(F16=3,1,-1))) -> 1 | X16: =IF(V16=1,G16+$B$2*W16*(B16-G16),G16) -> 0.91012213 | Y16: =IF(V16=1,H16+$B$2*W16*(C16-H16),H16) -> 0.074440715 | Z16: =IF(V16=1,I16+$B$2*W16*(D16-I16),I16) -> 0.64596957 | AA16: =IF(V16=1,J16+$B$2*W16*(E16-J16),J16) -> 0.85508601 | AB16: =IF(V16=2,K16+$B$2*W16*(B16-K16),K16) -> 0.59351242 | AC16: =IF(V16=2,L16+$B$2*W16*(C16-L16),L16) -> 0.36720259 | AD16: =IF(V16=2,M16+$B$2*W16*(D16-M16),M16) -> 0.4731069 | AE16: =IF(V16=2,N16+$B$2*W16*(E16-N16),N16) -> 0.48588205 | AF16: =IF(V16=3,O16+$B$2*W16*(B16-O16),O16) -> 0.14691827 | AG16: =IF(V16=3,P16+$B$2*W16*(C16-P16),P16) -> 0.82706265 | AH16: =IF(V16=3,Q16+$B$2*W16*(D16-Q16),Q16) -> 0.16886037 | AI16: =IF(V16=3,R16+$B$2*W16*(E16-R16),R16) -> 0.12599611
A17: 13 | B17: 0.90555556 | C17: 0.14457831 | D17: 0.66666667 | E17: 0.8 | F17: 1 | G17: =X16 -> 0.91012213 | H17: =Y16 -> 0.074440715 | I17: =Z16 -> 0.64596957 | J17: =AA16 -> 0.85508601 | K17: =AB16 -> 0.59351242 | L17: =AC16 -> 0.36720259 | M17: =AD16 -> 0.4731069 | N17: =AE16 -> 0.48588205 | ... R17: =AI16 -> 0.12599611 | S17: =SQRT((B17-G17)^2+(C17-H17)^2+(D17-I17)^2+(E17-J17)^2) -> 0.091667742 | T17: =SQRT((B17-K17)^2+(C17-L17)^2+(D17-M17)^2+(E17-N17)^2) -> 0.53204131 | U17: =SQRT((B17-O17)^2+(C17-P17)^2+(D17-Q17)^2+(E17-R17)^2) -> 1.3203817 | V17: =IF(S17=MIN(S17:U17),1,IF(T17=MIN(S17:U17),2,3)) -> 1 | W17: =IF(V17=1,IF(F17=1,1,-1),IF(V17=2,IF(F17=2,1,-1),IF(F17=3,1,-1))) -> 1 | X17: =IF(V17=1,G17+$B$2*W17*(B17-G17),G17) -> 0.90901245 | Y17: =IF(V17=1,H17+$B$2*W17*(C17-H17),H17) -> 0.091484151 | Z17: =IF(V17=1,I17+$B$2*W17*(D17-I17),I17) -> 0.65099897 | AA17: =IF(V17=1,J17+$B$2*W17*(E17-J17),J17) -> 0.84170011 | AB17: =IF(V17=2,K17+$B$2*W17*(B17-K17),K17) -> 0.59351242 | AC17: =IF(V17=2,L17+$B$2*W17*(C17-L17),L17) -> 0.36720259 | AD17: =IF(V17=2,M17+$B$2*W17*(D17-M17),M17) -> 0.4731069 | AE17: =IF(V17=2,N17+$B$2*W17*(E17-N17),N17) -> 0.48588205 | AF17: =IF(V17=3,O17+$B$2*W17*(B17-O17),O17) -> 0.14691827 | AG17: =IF(V17=3,P17+$B$2*W17*(C17-P17),P17) -> 0.82706265 | AH17: =IF(V17=3,Q17+$B$2*W17*(D17-Q17),Q17) -> 0.16886037 | AI17: =IF(V17=3,R17+$B$2*W17*(E17-R17),R17) -> 0.12599611
... A54: 50 | B54: 0 | C54: 1 | D54: 0.16666667 | E54: 0 | F54: 3 | G54: =X53 -> 0.91010537 | H54: =Y53 -> 0.084146099 | I54: =Z53 -> 0.67936776 | J54: =AA53 -> 0.8471001 | K54: =AB53 -> 0.59423093 | L54: =AC53 -> 0.36560244 | M54: =AD53 -> 0.47748346 | N54: =AE53 -> 0.48838096 | ... R54: =AI53 -> 0.17288893 | S54: =SQRT((B54-G54)^2+(C54-H54)^2+(D54-I54)^2+(E54-J54)^2) -> 1.6271205 | T54: =SQRT((B54-K54)^2+(C54-L54)^2+(D54-M54)^2+(E54-N54)^2) -> 1.0443628 | U54: =SQRT((B54-O54)^2+(C54-P54)^2+(D54-Q54)^2+(E54-R54)^2) -> 0.35303171 | V54: =IF(S54=MIN(S54:U54),1,IF(T54=MIN(S54:U54),2,3)) -> 3 | W54: =IF(V54=1,IF(F54=1,1,-1),IF(V54=2,IF(F54=2,1,-1),IF(F54=3,1,-1))) -> 1 | X54: =IF(V54=1,G54+$B$2*W54*(B54-G54),G54) -> 0.91010537 | Y54: =IF(V54=1,H54+$B$2*W54*(C54-H54),H54) -> 0.084146099 | Z54: =IF(V54=1,I54+$B$2*W54*(D54-I54),I54) -> 0.67936776 | AA54: =IF(V54=1,J54+$B$2*W54*(E54-J54),J54) -> 0.8471001 | AB54: =IF(V54=2,K54+$B$2*W54*(B54-K54),K54) -> 0.59423093 | AC54: =IF(V54=2,L54+$B$2*W54*(C54-L54),L54) -> 0.36560244 | AD54: =IF(V54=2,M54+$B$2*W54*(D54-M54),M54) -> 0.47748346 | AE54: =IF(V54=2,N54+$B$2*W54*(E54-N54),N54) -> 0.48838096 | AF54: =IF(V54=3,O54+$B$2*W54*(B54-O54),O54) -> 0.15084375 | AG54: =IF(V54=3,P54+$B$2*W54*(C54-P54),P54) -> 0.82241329 | AH54: =IF(V54=3,Q54+$B$2*W54*(D54-Q54),Q54) -> 0.16716493 | AI54: =IF(V54=3,R54+$B$2*W54*(E54-R54),R54) -> 0.13087692

Sheet Manual_Epoch4
A1: Perhitungan Manual LVQ - Epoch 4 (50 data)
A2: Alpha (α) | B2: 0.2187
